Workbook

Sheet Competency Mapping
A1: the organization 100 Competencies Mapping
A3: Matrix | B3: Marga Budaya the organization Mapping | C3: Competencies | D3: Assessment Method | E3: Activity
A5: Potential “How ready is this person for greater responsibility?” | B5: KARYA | C5: Profesionalisme | D5: Psychometry Assessment
B6: RAKSA | C6: Integritas
B7: SEVA | C7: Orientasi Pelanggan
B8: KARYA | C8: Penyempurnaan Tiada Henti
A9: Behavior “How consistently does this person demonstrate the expected behaviors during bootcamp?” | B9: RAKSA | C9: Karsa Satya | D9: Behavior Observation
B10: KARYA | C10: Karsa Daya
B11: SEVA | C11: Karsa Rasa
B12: KARYA | C12: Karsa Mahira
B13: KARYA | C13: Karsa Tumbuh
B14: KARYA | C14: Karsa Jaya
A16: Marga Budaya the organization: 4 Nilai: Jalan Budaya untuk Mewujudkan 4 Nilai dan 6 Karsa
A17: SEVA | B17: The Way We SERVE Customer First Empathy • Customer First • Experience Melayani pelanggan sepenuh hati dengan empati, tanggung jawab, dan solusi terbaik.
A18: KARYA | B18: The Way We PERFORM BRAVE Professional • Agile • Execute Berani berkarya dengan profesionalisme, kecepatan, dan penyempurnaan berkelanjutan.
A19: RAKSA | B19: The Way We PROTECT Zero Fraud Integrity • Risk-Aware • Trust Menjaga amanah melalui integritas, kesadaran risiko, dan keputusan yang bijaksana.
A21: 4 Nilai: Nilai yang melekat, relatif stabil, dan jadi kompas etika & perilaku
A22: Profesionalisme | B22: Memiliki kompetensi handal dan berkomitmen memberikan hasil terbaik.
A23: Integritas | B23: Berkomitmen untuk selalu konsisten antara pikiran, perkataan dan perbuatan yang dilandasi oleh katahati dan kepercayaan pada prinsipprinsip kebenaran yang hakiki.
A24: Orientasi Pelanggan | B24: Mengutamakan kepentingan pelanggan dengan dilandasi sikap saling menghargai dan hubungan kemitraan yang sinergis.
A25: Penyempurnaan Tiada Henti | B25: Senantiasa mencari peluang dan solusi untuk meningkatkan layanan dan kinerja yang melampaui harapan pelanggan.
A27: 6 Karsa: sebagai energi untuk mewujudkan nilai. bukan sekadar memahami nilai tetapi sebuah Tekad yang Menggerakkan Aksi
A28: Karsa Satya | B28: Being Sensitive to Risk Patuh pada peraturan, dapat dipercaya, peduli risiko dan berani mengungkapkan hal-hal yang tidak sesuai dengan peraturan
A29: Karsa Daya | B29: Navigating Agility, Grit Tidak mudah menyerah. tangguh, tekun, dan terus melangkah hingga tujuan tercapai.
A30: Karsa Rasa | B30: Customer First, Building Partnership Bekerja secara kolaboratif, berorientasi pada pencapaian solusi terbaik untuk kepentingan bank dan Proaktif memahami kebutuhan pelanggan serta dalam membangun hubungan baik dengan pelanggan maupun stakeholders lainnya.
A31: Karsa Mahira | B31: Being Proactive, Relevant to Market Memastikan hasil kerja memiliki standar tinggi dan Menerapkan proses kerja yang relevan, lincah, dan selaras dengan kebutuhan bisnis, guna menjawab ekspektasi pasar yang terus berkembang.
A32: Karsa Tumbuh | B32: Growth Oriented Terus menerus belajar, berinovasi, dan bertumbuh untuk menghadirkan solusi yang relevan dan adaptif terhadap dinamika pasar.
A33: Karsa Jaya | B33: Excel in Execution Unggul dalam eksekusi, bergerak untuk hasil, melangkah dengan arah yang jelas dan fokus pada hasil yang berdampak untuk memenangkan market share.
A35: Hastabrata: Hasta artinya delapan dan Brata yaitu perilaku atau tindakan pengendalian diri. Konsep Hastabrata dalam kitab tersebut bahwa pemimpin kekaisaran bertindak sesuai dengan karakter para dewa. Hastabrata pun menjadi tolok ukur sebuah kepemimpinan di masa itu.
A36: Bumi | B36: Pemimpin memiliki sifat murah hati dan adil terhadap semua pengikutnya. Pemimpin bersikap adil dengan memberikan penghargaan bagi para bawahan yang berprestasi tanpa membedakan statusnya.
A37: Matahari | B37: Pemimpin memiliki sifat berhati-hati dalam membimbing bawahannya. Pemimpin mampu memberikan dorongan energi kepada para bawahan secara perlahan, yang tanpa disadari akan membimbing bawahan menjalankan tujuan bersama.
A38: Api | B38: Pemimpin memiliki sifat tegas dalam memerintah, terutama saat memberikan hukuman pada bawahan yang melakukan kesalahan. Pemimpin harus berani mengambil keputusan untuk menghukum bahkan mengeluarkan bawahan yang bersalah dalam kelompok.
A39: Samudra | B39: Pemimpin memiliki sikap terbuka dan mampu menampung aspirasi dari para bawahannya. Pemimpin hendaknya bersikap bijak dalam menyikapi setiap kritik dari bawahan.
A40: Langit | B40: Pemimpin memiliki sifat mampu memberi nilai tambah keilmuan kepada para bawahannya. Pemimpin harus memiliki bekal keluasan pengetahuan atau kompetensi yang dapat diajarkan kepada para bawahan
A41: Angin | B41: Pemimpin memiliki sifat teliti ketika turun langsung memperhatikan atau mengawasi kinerja semua bawahan. Pemimpin harus berada dekat dengan bawahan tanpa membedakan statusnya.
A42: Bulan | B42: Pemimpin memiliki sifat periang yang mampu menyenangkan hati para bawahannya. Pemimpin mampu memberikan motivasi kepada para bawahan agar performa kinerjanya meningkat.
A43: Bintang | B43: Pemimpin memiliki sifat percaya diri dalam memegang teguh prinsip yang diyakininya. Prinsip kuat yang dimiliki pemimpin adalah pedoman bawahan dalam bekerjasama mencapai tujuan.

Sheet Activity Mapping
A1: No | B1: Activity | C1: Count | D1: SEVA | F1: KARYA | L1: RAKSA
D2: Potential | E2: Behavior/Assignment | F2: Potential | H2: Behavior/Assignment | L2: Potential | M2: Behavior/Assignment
D3: Orientasi Pelanggan | E3: Karsa Rasa Customer First | Building Partnership | F3: Profesionalisme | G3: Penyempurnaan Tiada Henti | H3: Karsa Daya Navigating Agility | I3: Karsa Mahira Being Proactive | Relevant to Market | J3: Karsa Tumbuh Growth Oriented | K3: Karsa Jaya Excel in Execution | L3: Integritas | M3: Karsa Satya Being Sensitive to Risk
D4: Mengutamakan kepentingan pelanggan dengan membangun sikap saling menghargai dan hubungan kemitraan yang sinergis. | E4: Bekerja secara kolaboratif, berorientasi pada pencapaian solusi terbaik untuk kepentingan bank, serta proaktif memahami kebutuhan pelanggan dan membangun hubungan yang baik dengan pelanggan maupun stakeholder lainnya. | F4: Memiliki kompetensi yang andal dan berkomitmen untuk memberikan hasil terbaik. | G4: Senantiasa mencari peluang dan solusi untuk meningkatkan layanan serta kinerja yang melampaui harapan pelanggan. | H4: Tidak mudah menyerah, tangguh, tekun, dan terus melangkah hingga tujuan tercapai. | I4: Memastikan hasil kerja memiliki standar tinggi, menerapkan proses kerja yang relevan, lincah, dan selaras dengan kebutuhan bisnis untuk menjawab ekspektasi pasar yang terus berkembang. | J4: Terus belajar, berinovasi, dan bertumbuh untuk menghadirkan solusi yang relevan serta adaptif terhadap dinamika pasar. | K4: Unggul dalam eksekusi, bergerak untuk menghasilkan dampak, melangkah dengan arah yang jelas, dan berfokus pada hasil yang berkontribusi terhadap peningkatan market share. | L4: Menjaga keselarasan antara pikiran, perkataan, dan perbuatan, serta berlandaskan pada kata hati, kepercayaan, dan prinsip kebenaran. | M4: Patuh terhadap peraturan, dapat dipercaya, peduli terhadap risiko, serta berani menyampaikan hal-hal yang tidak sesuai dengan ketentuan.
A5: 1 | B5: Psychometric Assessment | C5: 4 | D5: 1 | F5: 1 | G5: 1 | L5: 1
A6: 2 | B6: Black Box: Decoding of a Human Life | C6: 6 | E6: 0.5 | H6: 0.05 | I6: 0.4 | J6: 0.3 | K6: 0.4 | M6: 0.075
A7: 3 | B7: Solo Transmission: The Ascendant’s Stand | C7: 5 | E7: 0.4 | H7: 0.05 | I7: 0.1 | K7: 0.1 | M7: 0.075
A8: 4 | B8: Operation: the organization Protect | C8: 4 | E8: 0.1 | H8: 0.05 | I8: 0.1 | M8: 0.7
A9: 5 | B9: Dominion: Conquest of the Elements | C9: 4 | H9: 0.35 | I9: 0.3 | J9: 0.4 | K9: 0.4
A10: 6 | B10: XXX: Speed Coaching | H10: 0.3 | J10: 0.2
A11: 7 | B11: The Final Broadcast | C11: 5 | H11: 0.2 | I11: 0.1 | J11: 0.1 | K11: 0.1 | M11: 0.075
A12: 8 | B12: Anecdotal Observation | C12: 1 | M12: 0.075
D13: =SUM(D5:D12) | E13: =SUM(E5:E12) | F13: =SUM(F5:F12) | G13: =SUM(G5:G12) | H13: =SUM(H5:H12) | I13: =SUM(I5:I12) | J13: =SUM(J5:J12) | K13: =SUM(K5:K12) | ... M13: =SUM(M5:M12)

Sheet List Asesmen
A1: List All Assessment
A3: Pre-Event
A4: No | B4: Jenis Asesmen | C4: Metode | D4: PIC | E4: Kompetensi
A5: 1 | B5: Konstruk Hasta Brata (likert & rank) | C5: Google Form | D5: [redacted] | E5: Hasta Brata
A7: Day 1 | B7: Jenis Asesmen | C7: Metode
A8: 1 | B8: Launchpad: The Beginning of Everything | C8: Observasi | E8: Satya, Daya
A9: 2 | B9: The Signal: Voices from the Field | C9: Observasi | E9: Satya, Daya
A10: 3 | B10: Mission: Signal Decoding | C10: Observasi | E10: Daya, Rasa
A11: 4 | B11: Black Box: Decoding of a Human Life (1) | C11: Observasi | E11: Main Karsa Rasa Karsa Mahira Karsa Tumbuh Karsa Jaya Minor: Karsa Daya Karsa Satya
A12: 5 | B12: Black Box: Decoding of a Human Life (2) | C12: Panel Presentation Peer Assessment
A13: 6 | B13: Solo Transmission: The Ascendant’s Stand | C13: Assignment Evaluation | E13: Main: Karsa Rasa Minor: Karsa Daya Karsa Mahira Karsa Jaya
A14: 7 | B14: Recap Day 1
A16: Day 2 | B16: Jenis Asesmen | C16: Metode
A17: 1 | B17: Online Psychometry Assessment | C17: Individual Assignment | D17: [redacted] & Pulsifi
A18: 2 | B18: Operation: the organization Protect | C18: Observasi Assignment Evaluation | E18: Main: Karsa Satya Minor: Karsa Daya Karsa Mahira Karsa Rasa
A19: 3 | B19: Transmission: The Guardian’s Intel | C19: Observasi | E19: Satya, Daya
A20: 4 | B20: Mission: Ghost Protocol | C20: Observasi | E20: Daya, Rasa
A21: 5 | B21: Final Broadcast (Preparation) | C21: Observasi | E21: Daya, Rasa
A22: 6 | B22: Recap Day 2
A24: Day 3 | B24: Jenis Asesmen | C24: Metode
A25: 1 | B25: Ignition: The Call to Perform | C25: Observasi | E25: Karsa Daya Karsa Tumbuh Karsa Mahira Karsa Jaya
A26: 2 | B26: XXX: Speed Coaching | C26: Individual Assignment *Google Form Reflection | D26: [redacted] | E26: Karsa Tumbuh Karsa Jaya
A27: 3 | B27: Dominion: Conquest of the Elements | C27: Observasi | E27: Main: Karsa Daya Karsa Tumbuh Karsa Mahira Minor: Karsa Jaya
A28: 4 | B28: Final Broadcast (Preparation) | C28: xx | E28: xx
A29: 5 | B29: The Final Broadcast | C29: xx | E29: xx
A30: 6 | B30: Recap Day 3

Sheet Sheet1

Sheet Day 1 - 1. Launchpad
B2: Day 1: Launchpad: The Beginning of Everything
B3: Dalam Opening Ceremony, Senior Director the organization akan memberikan sambutan. Lalu dilanjutkan setiap individu dan kelompok diberikan waktu 10 menit untuk membuat perkenalan kelompok.
B4: Cara Pengisian: | E4: Mapping seats/ Inisial Peserta:
B5: 1. Perhatikan kompetensi dan indikator yang muncul pada peserta
B6: 2. Berikan score untuk setiap indikator perilaku yang dimunculkan mulai dar: 0-2
B7: 3 Berikan bukti perilaku konkret yang diucapkan / ditunjukkan peserta. Kalimat harus sebisa mungkin jelas dan benar - benar menggambarkan perilaku yang ditunjukkan peserta. Contoh: Peserta mengajukan pertanyaan terkait dengan implementasi 4 Nilai (Nadhi). [Verbatim]
B8: 4 Jika terdapat bukti perilaku yang mencerminkan kompetensi lainnya yang tidak ada di lembar observasi, observer diperbolehkan mencantumkannya pada bagian catatan di akhir formulir.
B11: Kompetensi | C11: Indikator Perilaku | D11: Contoh kalimat/perilaku | E11: Score 0 = Tidak terobservasi 1 = Terobservasi sebagian 2 = Terobservasi penuh (konsisten) | F11: Bukti Perilaku | H11: Kompetensi | I11: Score | J11: Band (per kegiatan)
H12: =B13 | I12: =IF(COUNT(E13:E16)=0,"",SUM(E13:E16)) | J12: =IF(COUNT(E13:E16)=0,"",IF(I12<=2,"Sangat Jarang / Tidak Muncul",IF(I12<=4,"Kadang-Kadang",IF(I12<=6,"Sering Muncul","Konsisten Muncul"))))
B13: Karsa Satya: General Observation | C13: Datang tepat waktu pada saat sesi | D13: Datang sebelum pembicara mulai menyampaikan materi 0 = terlambat (setelah pembicara sudah mulai) 1 = tepat waktu (sesaat pembicara mulai) | E13: 2 | F13: Pada awal sesi Launchpad: The Beginning of Everything, observasi kelompok mencatat [redacted] bersama peserta lain hadir sesuai waktu kegiatan. Rincian yang terlihat: Datang tepat waktu; observasi kelompok: datang tepat waktu. | H13: =B17 | I13: =IF(COUNT(E17:E20)=0,"",SUM(E17:E20)) | J13: =IF(COUNT(E17:E20)=0,"",IF(I13<=2,"Sangat Jarang / Tidak Muncul",IF(I13<=4,"Kadang-Kadang",IF(I13<=6,"Sering Muncul","Konsisten Muncul"))))
C14: Berpakaian rapi sesuai ketentuan aturan the organization | D14: Menggunakan dresscode rapi sesuai dengan ketentuan aturan the organization. Day 1: Professional office Day 2: Berbatik Day 3: Kaos Peserta + Blazer 0= salah dresscode 1= kurang rapi dengan ketentuan the organization 2 = sesuai ketentuan the organization | E14: 2 | F14: Untuk aspek kerapian dan kesesuaian busana di sesi Launchpad: The Beginning of Everything, [redacted] dengan penampilan yang terlihat sebagai berikut: Menggunakan baju hitam profesional dengan blazer abu-abu.
C15: Menunjukkan fokus dan perhatian penuh saat pembicara memaparkan materi. | D15: 0 = Melakukan aktivitas lain hampir di seluruh sesi ketika orang lain berbicara (main hp, bermain laptop, tidur, keluar untuk waktu lama). 1 = Sesekali 2 = Full Atensi | E15: 2 | F15: Saat sesi Launchpad berlangsung, [redacted] sering mengangguk ketika pembicara menyampaikan materi dan mencatat poin visi-misi. Perilakunya terlihat fokus sepanjang sesi.
C16: Menunjukkan etika profesional dan memberikan respons apresiatif terhadap jalannya forum. | D16: Memberikan reaksi yang pantas saat berinteraksi dengan pembicara/MC (tidak hanya diam mematung). 1 = Merespons sapaan/instruksi sesekali saja, namun terkesan formalitas atau kurang antusias. 2 = Proaktif memberikan respons (menjawab salam, bertepuk tangan di momen yang tepat) | E16: 2 | F16: Dalam momen respons forum pada sesi Launchpad: The Beginning of Everything, [redacted] Ikut respons/yel bersama kelompok saat diminta menjawab semangat pagi.
B17: Karsa Daya: GRIT | C17: Tetap fokus dan menunjukkan keterlibatan aktif sepanjang sesi meskipun durasi panjang atau materi kompleks | D17: Peserta mencatat poin penting dan merespons pertanyaan dari moderator tetap engaged sampai sesi akhir | E17: 2 | F17: Sepanjang sesi Launchpad: The Beginning of Everything, [redacted] Menunjukkan perhatian aktif dan mencatat restatement visi-misi.
C18: Mengajukan pertanyaan atau komentar yang menunjukkan ketekunan dalam memahami materi, bukan sekadar permukaan | D18: Contoh pertanyaan: Tadi Ibu sebut logistik ekspor sempat drop saat kurs meningkat. Apa strategi baru yang akhirnya berhasil menjaga volume? | E18: 0 | F18: Pada sesi Launchpad: The Beginning of Everything, tidak ada segmen tanya jawab atau forum komentar substantif. Peserta tidak memiliki kesempatan terstruktur untuk mengajukan pertanyaan atau komentar mendalam pada indikator ini.
C19: Mempertahankan bahasa tubuh yang antusias sepanjang durasi acara. | D19: Tidak menunjukkan bahasa tubuh yang pasrah atau kelelahan ekstrem, terpisah dari sekadar "tidak main HP". 0 = Menunjukkan bahasa tubuh yang sangat malas (bersandar pasrah merosot di kursi, menunduk terus, wajah ditekuk) di sebagian besar sesi. 1 = Berusaha duduk tegak, namun sesekali terlihat sangat kelelahan, menguap lebar berulang kali, atau merebahkan kepala sesaat. 2 = Konsisten mempertahankan postur antusias (duduk tegap, pandangan mengarah ke panggung) dan menyimak sesi dari awal hingga akhir. | E19: 2 | F19: Dari sisi bahasa tubuh selama sesi Launchpad: The Beginning of Everything, [redacted] Bahasa tubuh aktif melalui nodding berulang saat HC berbicara.
C20: Menunjukkan ketekunan menyimak pada saat sesi diskusi/Tanya Jawab (Q&A) berlangsung, meskipun bukan dirinya yang bertanya. | D20: Mengukur fokus peserta saat mendengar pertanyaan dari rekan lain dan jawaban dari pembicara. 0 = Langsung check-out (mulai ngobrol santai dengan sebelah, membuka HP, atau terlihat tidak peduli) begitu sesi Q&A dimulai. 1 = Tetap melihat ke arah panggung, namun pasif dan terlihat bosan/menurun fokusnya dibandingkan saat materi utama. 2 = Menyimak pertanyaan dari peserta lain dan jawaban dari pembicara dengan saksama (sama seriusnya dengan saat mendengarkan materi utama). | E20: 0 | F20: Pada sesi Launchpad: The Beginning of Everything, tidak ada segmen Q&A. Tidak ada momen bagi peserta untuk menyimak pertanyaan peserta lain beserta jawaban narasumber pada indikator ini.

Sheet Day 1 - 2. Talkshow
B2: Day 1: Talkshow: The Signal: Voices from the Field
B3: Sesi talk show akan dibagi menjadi 3 bagian: sharing, QnA, dan wrap-up.
B4: Cara Pengisian: | E4: Mapping seats/ Inisial Peserta:
B5: 1. Perhatikan kompetensi dan indikator yang muncul pada peserta
B6: 2. Berikan score untuk setiap indikator perilaku yang dimunculkan mulai dar: 0-2
B7: 3 Berikan bukti perilaku konkret yang diucapkan / ditunjukkan peserta. Kalimat harus sebisa mungkin jelas dan benar - benar menggambarkan perilaku yang ditunjukkan peserta. Contoh: Peserta mengajukan pertanyaan terkait dengan implementasi 4 Nilai (Nadhi). [Verbatim]
B8: 4 Jika terdapat bukti perilaku yang mencerminkan kompetensi lainnya yang tidak ada di lembar observasi, observer diperbolehkan mencantumkannya pada bagian catatan di akhir formulir.
B11: Kompetensi | C11: Indikator Perilaku | D11: Contoh kalimat/perilaku | E11: Score 0 = Tidak terobservasi 1 = Terobservasi sebagian 2 = Terobservasi penuh (konsisten) | F11: Bukti Perilaku | H11: Kompetensi | I11: Score | J11: Band (per kegiatan)
H12: =B13 | I12: =IF(COUNT(E13:E16)=0,"",SUM(E13:E16)) | J12: =IF(COUNT(E13:E16)=0,"",IF(I12<=2,"Sangat Jarang / Tidak Muncul",IF(I12<=4,"Kadang-Kadang",IF(I12<=6,"Sering Muncul","Konsisten Muncul"))))
B13: Karsa Satya: General Observation | C13: Datang tepat waktu pada saat sesi | D13: Datang sebelum pembicara mulai menyampaikan materi 0 = terlambat (setelah pembicara sudah mulai) 1 = tepat waktu (sesaat pembicara mulai) | E13: 2 | F13: Pada awal sesi The Signal: Voices from the Field, observasi kelompok mencatat [redacted] bersama peserta lain hadir sesuai waktu kegiatan. Rincian yang terlihat: Datang dari cafe break tepat waktu bersama kelompok. | H13: =B17 | I13: =IF(COUNT(E17:E20)=0,"",SUM(E17:E20)) | J13: =IF(COUNT(E17:E20)=0,"",IF(I13<=2,"Sangat Jarang / Tidak Muncul",IF(I13<=4,"Kadang-Kadang",IF(I13<=6,"Sering Muncul","Konsisten Muncul"))))
C14: Berpakaian rapi sesuai ketentuan aturan the organization | D14: Menggunakan dresscode rapi sesuai dengan ketentuan aturan the organization. Day 1: Professional office Day 2: Berbatik Day 3: Kaos Peserta + Blazer 0= salah dresscode 1= kurang rapi dengan ketentuan the organization 2 = sesuai ketentuan the organization | E14: 2 | F14: Untuk aspek kerapian dan kesesuaian busana di sesi The Signal: Voices from the Field, observasi kelompok mencatat [redacted] bersama peserta lain dengan penampilan yang terlihat sebagai berikut: Berpakaian rapi sesuai observasi kelompok.
C15: Menunjukkan fokus dan perhatian penuh saat pembicara memaparkan materi. | D15: 0 = Melakukan aktivitas lain hampir di seluruh sesi ketika orang lain berbicara (main hp, bermain laptop, tidur, keluar untuk waktu lama). 1 = Sesekali 2 = Full Atensi | E15: 2 | F15: Saat materi atau instruksi berlangsung dalam sesi The Signal: Voices from the Field, [redacted] mencatat yang disampaikan pemateri.
C16: Menunjukkan etika profesional dan memberikan respons apresiatif terhadap jalannya forum. | D16: Memberikan reaksi yang pantas saat berinteraksi dengan pembicara/MC (tidak hanya diam mematung). 1 = Merespons sapaan/instruksi sesekali saja, namun terkesan formalitas atau kurang antusias. 2 = Proaktif memberikan respons (menjawab salam, bertepuk tangan di momen yang tepat) | E16: 2 | F16: Dalam momen respons forum pada sesi The Signal: Voices from the Field, [redacted] Tepuk tangan saat jawaban pertanyaan kelompok lain terjawab.
B17: Karsa Daya: GRIT | C17: Tetap fokus dan menunjukkan keterlibatan aktif sepanjang sesi meskipun durasi panjang atau materi kompleks | D17: Peserta mencatat poin penting dan merespons pertanyaan dari moderator, tetap engaged sampai sesi akhir | E17: 2 | F17: Sepanjang sesi The Signal: Voices from the Field, [redacted] mencatat materi pemateri sampai sesi berjalan.
C18: Mengajukan pertanyaan atau komentar yang menunjukkan ketekunan dalam memahami materi, bukan sekadar permukaan | D18: Contoh pertanyaan: Tadi Ibu sebut logistik ekspor sempat drop saat kurs meningkat. Apa strategi baru yang akhirnya berhasil menjaga volume? | E18: 2 | F18: Pada sesi The Signal: Voices from the Field, [redacted] mengangkat tangan untuk bertanya kepada pemateri.
C19: Mempertahankan bahasa tubuh yang antusias sepanjang durasi acara. | D19: Tidak menunjukkan bahasa tubuh yang pasrah atau kelelahan ekstrem, terpisah dari sekadar "tidak main HP". 0 = Menunjukkan bahasa tubuh yang sangat malas (bersandar pasrah merosot di kursi, menunduk terus, wajah ditekuk) di sebagian besar sesi. 1 = Berusaha duduk tegak, namun sesekali terlihat sangat kelelahan, menguap lebar berulang kali, atau merebahkan kepala sesaat. 2 = Konsisten mempertahankan postur antusias (duduk tegap, pandangan mengarah ke panggung) dan menyimak sesi dari awal hingga akhir. | E19: 2 | F19: Dari sisi bahasa tubuh selama sesi The Signal: Voices from the Field, [redacted] Tetap terlibat melalui catatan dan respons selama sesi.
C20: Menunjukkan ketekunan menyimak pada saat sesi diskusi/Tanya Jawab (Q&A) berlangsung, meskipun bukan dirinya yang bertanya. | D20: Mengukur fokus peserta saat mendengar pertanyaan dari rekan lain dan jawaban dari pembicara. 0 = Langsung check-out (mulai ngobrol santai dengan sebelah, membuka HP, atau terlihat tidak peduli) begitu sesi Q&A dimulai. 1 = Tetap melihat ke arah panggung, namun pasif dan terlihat bosan/menurun fokusnya dibandingkan saat materi utama. 2 = Menyimak pertanyaan dari peserta lain dan jawaban dari pembicara dengan saksama (sama seriusnya dengan saat mendengarkan materi utama). | E20: 2 | F20: Saat sesi tanya jawab The Signal: Voices from the Field berlangsung, [redacted] menyimak pertanyaan dari kelompok lain hingga jawaban pemateri selesai.

Sheet Day 1 - 3. Mission
B2: Day 1: Mission: Signal Decoding
B5: Cara Pengisian: | E5: Mapping seats/ Inisial Peserta:
B6: 1. Perhatikan kompetensi dan indikator yang muncul pada peserta
B7: 2. Berikan score untuk setiap indikator perilaku yang dimunculkan mulai dar: 0-2
B8: 3 Berikan bukti perilaku konkret yang diucapkan / ditunjukkan peserta. Kalimat harus sebisa mungkin jelas dan benar - benar menggambarkan perilaku yang ditunjukkan peserta. Contoh: Peserta mengajukan pertanyaan terkait dengan implementasi 4 Nilai (Nadhi). [Verbatim]
B9: 4 Jika terdapat bukti perilaku yang mencerminkan kompetensi lainnya yang tidak ada di lembar observasi, observer diperbolehkan mencantumkannya pada bagian catatan di akhir formulir.
B12: Kompetensi | C12: Indikator Perilaku | D12: Contoh kalimat/perilaku | E12: Score 0 = Tidak terobservasi 1 = Terobservasi sebagian 2 = Terobservasi penuh (konsisten) | F12: Bukti Perilaku | H12: Kompetensi | I12: Score | J12: Band (per kegiatan)
H13: =B14 | I13: =IF(COUNT(E14:E17)=0,"",SUM(E14:E17)) | J13: =IF(COUNT(E14:E17)=0,"",IF(I13<=2,"Sangat Jarang / Tidak Muncul",IF(I13<=4,"Kadang-Kadang",IF(I13<=6,"Sering Muncul","Konsisten Muncul"))))
B14: Karsa Daya: GRIT & Navigating Agility | C14: Menunjukkan keterlibatan aktif dalam proses penyelesaian tantangan pada setiap ronde | D14: adaptive communication | E14: 2 | F14: Sepanjang aktivitas Mission: Signal Decoding, [redacted] menjelaskan pemahaman instruksi ke anggota lain; memberi ide clue yang perlu ditulis. | H14: =B18 | I14: =IF(COUNT(E18:E21)=0,"",SUM(E18:E21)) | J14: =IF(COUNT(E18:E21)=0,"",IF(I14<=2,"Sangat Jarang / Tidak Muncul",IF(I14<=4,"Kadang-Kadang",IF(I14<=6,"Sering Muncul","Konsisten Muncul"))))
C15: Tidak menunjukkan sikap negatif seperti mengeluh dan menyerah ketika kelompok mengalami kesulitan | D15: strategic adjustment, | E15: 2 | F15: Saat kelompok menghadapi proses kerja dalam aktivitas Mission: Signal Decoding, [redacted] Tetap mengikuti diskusi instruksi dan proses permainan bersama kelompok.
C16: Menunjukkan keterbukaan terhadap cara kerja atau ide baru dalam kelompok | D16: openness, | E16: 2 | F16: Ketika muncul usulan cara kerja dalam aktivitas Mission: Signal Decoding, [redacted] Terbuka dengan suggestion anggota lain terkait deskripsi fisik.
C17: Mengambil keputusan sesuai situasi yang berkembang selama aktivitas berlangsung | D17: Situational judgment. Saat ada anggota tim mencurigainya, tetap fokus pada tugas & tidak terprovokasi emosional. | E17: 2 | F17: Pada dinamika pengambilan keputusan di aktivitas Mission: Signal Decoding, [redacted] Mengusulkan clue yang perlu ditulis sebagai penyesuaian cara kerja.
B18: Karsa Rasa: Building Partnership | C18: Memberikan kesempatan kepada anggota tim untuk menyampaikan pendapat | D18: Proaktif mengajak yang lebih diam. contoh: "Menurutmu strategi ambil piece-nya gimana?" | E18: 2 | F18: Dalam aktivitas Mission: Signal Decoding, [redacted] paling aktif memberi ruang dan mengajak anggota lain terlibat dalam pembahasan instruksi maupun strategi kelompok.
C19: Menunjukkan sikap terbuka terhadap masukan dari anggota tim, seperti tidak memotong pembicaraan, mengakui ide rekan sebelum menambahkan/mengoreksi, meminta klarifikasi sebelum menolak ide | D19: "Idemu bagus. Ide itu bisa juga diintegrasikan dengan pakai daftar prioritas piece-nya, kita lebih efisien." | E19: 2 | F19: Dalam aktivitas Mission: Signal Decoding, [redacted] terbuka terhadap masukan anggota tim. Tidak terlihat perilaku memotong, defensif, atau menolak ide anggota lain.
C20: Mendorong terciptanya kesepahaman sebelum kelompok mengambil keputusan | D20: Merangkum kesepakatan sebelum lanjut ke topik berikutnya, Cek pemahaman secara eksplisit, Mengangkat hal yang belum dibahas sebelum waktu habis, dll | E20: 2 | F20: Dalam aktivitas Mission: Signal Decoding, [redacted] menjelaskan pemahaman instruksi kepada anggota lain untuk membantu tim menyamakan pemahaman sebelum bergerak ke tahap berikutnya.
C21: Menunjukkan upaya menjaga kerja sama kelompok tetap kondusif selama aktivitas berlangsung | D21: Saat suasana mulai tegang karena kecurigaan, peserta berusaha mendinginkan | E21: 2 | F21: Sebelum aktivitas Mission: Signal Decoding dimulai dan sebelum kelompok dibagi menjadi dua tim, [redacted] ikut menyuarakan jargon kelompok bersama anggota lain.

Sheet Day 1 - 4. Black Box
B2: Day 1: Black Box: Decoding of a Human Life
B4: Cara Pengisian: | E4: Mapping seats/ Inisial Peserta:
B5: 1. Perhatikan kompetensi dan indikator yang muncul pada peserta
B6: 2. Berikan score untuk setiap indikator perilaku yang dimunculkan mulai dar: 0-2
B7: 3 Berikan bukti perilaku konkret yang diucapkan / ditunjukkan peserta. Kalimat harus sebisa mungkin jelas dan benar - benar menggambarkan perilaku yang ditunjukkan peserta. Contoh: Peserta mengajukan pertanyaan terkait dengan implementasi 4 Nilai (Nadhi). [Verbatim]
B8: 4 Jika terdapat bukti perilaku yang mencerminkan kompetensi lainnya yang tidak ada di lembar observasi, observer diperbolehkan mencantumkannya pada bagian catatan di akhir formulir.
B11: Kompetensi | C11: Indikator Perilaku | D11: Contoh kalimat/perilaku | E11: Score 0 = Tidak terobservasi 1 = Terobservasi sebagian 2 = Terobservasi penuh (konsisten) | F11: Bukti Perilaku | H11: Kompetensi | I11: Score | J11: Band (per kegiatan)
H12: =B13 | I12: =IF(COUNT(E13:E16)=0,"",SUM(E13:E16)) | J12: =IF(COUNT(E13:E16)=0,"",IF(I12<=2,"Sangat Jarang / Tidak Muncul",IF(I12<=4,"Kadang-Kadang",IF(I12<=6,"Sering Muncul","Konsisten Muncul"))))
B13: Karsa Rasa: Customer First | C13: Menggunakan informasi dari dokumen nasabah sebagai dasar diskusi kelompok | E13: 2 | F13: Pada tahap membaca bahan nasabah dalam Black Box, [redacted] mencatat instruksi, profil nasabah, dan poin hasil diskusi untuk digunakan dalam pembahasan kelompok. | H13: =B17 | I13: =IF(COUNT(E17:E20)=0,"",SUM(E17:E20)) | J13: =IF(COUNT(E17:E20)=0,"",IF(I13<=2,"Sangat Jarang / Tidak Muncul",IF(I13<=4,"Kadang-Kadang",IF(I13<=6,"Sering Muncul","Konsisten Muncul"))))
C14: Mengajukan pertanyaan yang relevan saat phone booth call untuk memahami kondisi nasabah (follow up question, bukan hanya validasi checklist) | E14: 2 | F14: Saat kelompok menyiapkan sesi panggilan nasabah, [redacted] menitipkan pertanyaan tentang jumlah rumah yang terjual per bulan. | H14: =B21 | I14: =IF(COUNT(E21:E24)=0,"",SUM(E21:E24)) | J14: =IF(COUNT(E21:E24)=0,"",IF(I14<=2,"Sangat Jarang / Tidak Muncul",IF(I14<=4,"Kadang-Kadang",IF(I14<=6,"Sering Muncul","Konsisten Muncul"))))
C15: Menghubungkan solusi yang dibahas dengan kebutuhan nasabah yang ditemukan | E15: 2 | F15: Dalam pembahasan solusi nasabah, [redacted] mengaitkan diskusi dengan target harga, jaminan yang dimiliki nasabah, dan jumlah rumah yang terjual per bulan. | H15: =B25 | I15: =IF(COUNT(E25:E28)=0,"",SUM(E25:E28)) | J15: =IF(COUNT(E25:E28)=0,"",IF(I15<=2,"Sangat Jarang / Tidak Muncul",IF(I15<=4,"Kadang-Kadang",IF(I15<=6,"Sering Muncul","Konsisten Muncul"))))
C16: Menghindari asumsi terhadap kebutuhan nasabah tanpa informasi yang memadai | E16: 2 | F16: Untuk mengurangi asumsi dalam Black Box, [redacted] menanyakan jaminan nasabah dan jumlah rumah yang terjual per bulan sebagai dasar pembahasan. | H16: =B29 | I16: =IF(COUNT(E29:E32)=0,"",SUM(E29:E32)) | J16: =IF(COUNT(E29:E32)=0,"",IF(I16<=2,"Sangat Jarang / Tidak Muncul",IF(I16<=4,"Kadang-Kadang",IF(I16<=6,"Sering Muncul","Konsisten Muncul"))))
B17: Karsa Rasa: Building Partnership | C17: Memberikan kesempatan anggota tim menyampaikan pendapat dalam proses analisis | E17: 0 | F17: Dalam proses analisis Black Box, tidak terlihat momen [redacted] secara khusus memberi ruang bicara kepada anggota yang diam. | H17: =B33 | I17: =IF(COUNT(E33:E36)=0,"",SUM(E33:E36)) | J17: =IF(COUNT(E33:E36)=0,"",IF(I17<=2,"Sangat Jarang / Tidak Muncul",IF(I17<=4,"Kadang-Kadang",IF(I17<=6,"Sering Muncul","Konsisten Muncul"))))
C18: Menunjukkan sikap terbuka terhadap masukan dari anggota tim, seperti tidak memotong pembicaraan | E18: 2 | F18: Dalam diskusi Black Box, [redacted] mendengarkan masukan anggota lain dan merespons positif saat anggota lain menyampaikan saran. | H18: =B37 | I18: =IF(COUNT(E37:E40)=0,"",SUM(E37:E40)) | J18: =IF(COUNT(E37:E40)=0,"",IF(I18<=2,"Sangat Jarang / Tidak Muncul",IF(I18<=4,"Kadang-Kadang",IF(I18<=6,"Sering Muncul","Konsisten Muncul"))))
C19: Mendorong terciptanya kesepahaman sebelum kelompok mengambil keputusan | E19: 2 | F19: Sebelum kelompok melanjutkan keputusan dalam Black Box, [redacted] membantu menjelaskan pemahaman kepada [redacted], [redacted], dan [redacted]. | H19: =B41 | I19: =IF(COUNT(E41:E44)=0,"",SUM(E41:E44)) | J19: =IF(COUNT(E41:E44)=0,"",IF(I19<=2,"Sangat Jarang / Tidak Muncul",IF(I19<=4,"Kadang-Kadang",IF(I19<=6,"Sering Muncul","Konsisten Muncul"))))
C20: Menunjukkan upaya menjaga kerja sama kelompok tetap kondusif selama aktivitas berlangsung | E20: 2 | F20: Selama kerja kelompok Black Box, [redacted] bekerja dalam situasi kelompok yang kondusif. Tidak terlihat konflik atau perilaku saling menyalahkan antaranggota. | H20: =B45 | I20: =IF(COUNT(E45:E48)=0,"",SUM(E45:E48)) | J20: =IF(COUNT(E45:E48)=0,"",IF(I20<=2,"Sangat Jarang / Tidak Muncul",IF(I20<=4,"Kadang-Kadang",IF(I20<=6,"Sering Muncul","Konsisten Muncul"))))
B21: Karsa Mahira: Being Proactive | C21: Mengusulkan langkah kerja untuk membantu kelompok bergerak lebih efektif | E21: 2 | F21: Pada pengaturan proses kerja Black Box, [redacted] membantu mengarahkan pembahasan melalui target harga dan pertanyaan yang perlu dibawa ke sesi panggilan nasabah.
C22: Secara aktif mencari informasi penting dari dokumen yang tersedia | E22: 2 | F22: Saat menelusuri bahan kasus Black Box, [redacted] mencatat profil nasabah dan hasil diskusi untuk membantu pembahasan kelompok.
C23: Mengambil peran tambahan ketika kelompok membutuhkan bantuan | E23: 1 | F23: Di luar diskusi utama Black Box, [redacted] membantu menyusun poin yang perlu dimasukkan ke materi presentasi.
C24: Bertindak cepat untuk memberikan solusi saat melihat hambatan yang berpotensi mengganggu proses pengerjaan | E24: 1 | F24: Ketika proses Black Box berjalan dengan waktu terbatas, [redacted] membantu menyiapkan pertanyaan dan poin presentasi. Namun kelompok terlambat antre sehingga tidak mendapat sesi panggilan pertama.
B25: Karsa Mahira: Relevant to Market | C25: Menghubungkan kebutuhan nasabah dengan produk/solusi the organization yang paling sesuai | E25: 2 | F25: Dalam pengaitan kebutuhan nasabah dengan opsi solusi the organization, [redacted] menunjukkan pengetahuan yang luas tentang kebutuhan nasabah dan solusi the organization yang dapat digunakan.
C26: Menunjukkan pemahaman terhadap penggunaan produk sesuai kebutuhan nasabah | E26: 2 | F26: Pada pembahasan penggunaan produk dalam Black Box, [redacted] menunjukkan pemahaman terhadap kebutuhan nasabah dan opsi solusi the organization yang sesuai.
C27: Mengaitkan pembahasan kelompok dengan konteks kebutuhan bisnis the organization | E27: 2 | F27: Saat diskusi diarahkan ke konteks bisnis the organization dalam Black Box, [redacted] mengaitkan kebutuhan nasabah dengan produk, jaminan, target harga, dan kondisi penjualan rumah.
C28: Menghubungkan isu eksternal (ekonomi, sosial, teknologi) dengan solusi yang diberikan pada nasabah | E28: 0 | F28: Dalam Black Box, [redacted] tidak terlihat menghubungkan isu eksternal seperti ekonomi, sosial, teknologi, kondisi pasar, atau kompetitor bank dengan solusi nasabah.
B29: Karsa Tumbuh: Growth Oriented | C29: Mengajukan klarifikasi untuk memperdalam pemahaman terhadap kasus | E29: 2 | F29: Pada saat memperdalam pemahaman kasus Black Box, [redacted] mengajukan klarifikasi tentang jaminan dan jumlah rumah yang terjual per bulan.
C30: Berbagi pengetahuan atau informasi yang membantu proses kelompok | D30: Berbagi insight/pembelajaran baru yang baru saja diperoleh dari analisis dokumen/call/pengalaman/produk the organization | E30: 2 | F30: Dalam pertukaran informasi kelompok Black Box, [redacted] membantu menjelaskan informasi kepada [redacted], [redacted], dan [redacted].
C31: Mengusulkan pendekatan atau ide baru dalam penyusunan solusi keuangan nasabah | E31: 2 | F31: Ketika kelompok menyusun pendekatan solusi Black Box, [redacted] mengusulkan fokus pada target harga, jaminan, dan jumlah rumah terjual per bulan.
C32: Mengembangkan ide kelompok agar solusi yang ditawarkan lebih menarik bagi nasabah | E32: 2 | F32: Pada proses memperkaya solusi kelompok Black Box, [redacted] mengembangkan ide melalui pertanyaan jaminan, target harga, dan jumlah rumah terjual.
B33: Karsa Jaya: Excel in Execution | C33: Menyusun rencana kerja dengan target waktu dan hasil yang jelas | E33: 0 | F33: Dalam Black Box, [redacted] memiliki cara masing-masing untuk menganalisis kasus, tetapi tidak terlihat adanya goal setting kelompok atau target kerja bersama yang jelas.
C34: Mendistribusikan tugas secara strategis dan memonitor progres kerja kelompok | E34: 0 | F34: Dalam Black Box, [redacted] bekerja mengikuti alur spontan kelompok. Tidak terlihat pembagian tugas strategis atau monitoring progres yang jelas.
C35: Memberikan masukan yang membangun untuk meningkatkan kualitas output kelompok | D35: "Ini bisa lebih tajam lagi enggak?" | E35: 2 | F35: Pada penyusunan output Black Box, [redacted] membantu poin presentasi dan menjelaskan informasi kepada anggota lain untuk memperbaiki bahan kelompok.
C36: Menyelesaikan bagian sendiri dengan tepat waktu dan kualitas tinggi sebelum final check bersama | E36: 1 | F36: Menjelang penyelesaian output Black Box, [redacted] membantu poin presentasi dan pertanyaan call, tetapi bukan pemilik bagian teknis utama.
B37: Karsa Daya: GRIT & Navigating Agility | C37: Menunjukkan keterlibatan aktif dalam proses penyelesaian tantangan pada setiap ronde (tidak menurun di tengah/akhir) | E37: 2 | F37: Selama proses Black Box, [redacted] aktif mencatat, mengusulkan pertanyaan, membantu poin presentasi, dan menjelaskan informasi kepada anggota lain.
C38: Tidak menunjukkan sikap negatif seperti mengeluh dan menyerah ketika kelompok mengalami kesulitan | E38: 2 | F38: Saat kelompok menghadapi kesulitan dalam Black Box, termasuk ketika terlambat antre dan tidak mendapat sesi panggilan pertama, [redacted] tidak terlihat mengeluh atau menyerah.
C39: Menunjukkan keseriusan dalam menyelesaikan tantangan yang diberikan kelompok | D39: tetap fokus & tekun saat menganalisis 10 dokumen yang melelahkan, tanpa shortcut) | E39: 2 | F39: Saat pengerjaan kasus Black Box berlangsung, [redacted] serius mencatat, mengajukan pertanyaan relevan, dan membantu penjelasan kepada anggota lain.
C40: Menunjukkan dorongan untuk membantu kelompok mencapai hasil terbaik | D40: memberikan solusi yang relevan / solutif; solutif = dipakai) | E40: 2 | F40: Dalam upaya kelompok menyelesaikan Black Box, [redacted] kuat membantu kelompok melalui pertanyaan nasabah, poin presentasi, dan penjelasan kepada anggota lain.
B41: Karsa Satya: Being Sensitive to Risk | C41: Mengidentifikasi & berani mengungkapkan potensi risiko dari solusi yang akan diberikan kepada nasabah | E41: 1 | F41: Pada pembahasan risiko solusi Black Box, [redacted] menanyakan jaminan nasabah yang relevan dengan kehati-hatian solusi.
C42: Menunjukkan perhatian terhadap keamanan dan kerahasiaan informasi nasabah selama aktivitas | E42: 1 | F42: Terkait keamanan dan kerahasiaan informasi nasabah dalam Black Box, tidak terlihat perilaku khusus dari [redacted] yang secara aktif menjaga kerahasiaan; tidak terlihat pula pelanggaran kerahasiaan.
C43: Memverifikasi data sebelum digunakan sebagai dasar solusi (menghindari pengunaan asumsi) | E43: 2 | F43: Saat data digunakan sebagai dasar solusi Black Box, [redacted] memverifikasi melalui pertanyaan tentang jaminan dan jumlah rumah yang terjual per bulan.
C44: Mempertimbangkan aspek kepatuhan atau kesesuaian aturan dalam solusi yang diusulkan | E44: 1 | F44: Pada aspek kepatuhan atau kesesuaian aturan dalam Black Box, [redacted] relevan secara tidak langsung melalui pertanyaan tentang jaminan nasabah.
...

Sheet Day 1 - 5. Peer Black Box
B2: Day 1: Black Box: Decoding of a Human Life
B4: Cara Pengisian:
B5: Setiap kelompok akan memberikan penilaian pada kelompok lainnya pada 3 kelompok lainnya di ruangan yang sama
B6: Penilaian dilakukan menggunakan skala 1–5 pada setiap aspek yang dinilai.
B7: Berikan penilaian kepada presentasi kelompok lainnya berdasarkan presentasi yang berlangsung
B8: Berikan penilaian secara objektif dan profesional.
B9: Panduan deskripsi untuk setiap skala penilaian telah disediakan sebagai acuan dalam memberikan nilai.
B11: Kompetensi | C11: Item Penilaian | D11: 1 | E11: 2 | F11: 3 | G11: 4 | H11: 5 | I11: Score | K11: Kompetensi | L11: Score | M11: Band (per kegiatan)
B12: Karsa Rasa: Customer First | C12: Kelompok menunjukkan pemahaman yang mendalam terhadap kebutuhan, kondisi, dan prioritas nasabah | D12: Kelompok belum mampu menunjukkan pemahaman terhadap kondisi, kebutuhan, maupun prioritas nasabah. Analisis yang disampaikan masih bersifat umum, tidak relevan, atau tidak didukung informasi dari dokumen dan hasil interaksi dengan nasabah. | E12: Kelompok mulai menunjukkan upaya memahami kondisi nasabah, namun analisis yang disampaikan masih terbatas, kurang mendalam, dan masih didominasi asumsi yang belum terverifikasi. | F12: Kelompok mampu mengidentifikasi kebutuhan dan kondisi utama nasabah berdasarkan informasi yang tersedia, namun pemahaman yang ditunjukkan masih pada level dasar dan belum sepenuhnya menggambarkan prioritas nasabah secara menyeluruh. | G12: Kelompok menunjukkan pemahaman yang baik terhadap kondisi, kebutuhan, dan prioritas nasabah melalui analisis yang relevan dan didukung data atau informasi yang tersedia selama aktivitas. | H12: Kelompok menunjukkan pemahaman yang mendalam dan menyeluruh terhadap kebutuhan, kondisi, dan prioritas nasabah, serta mampu menangkap konteks dan pertimbangan penting yang memengaruhi kebutuhan nasabah secara tepat dan relevan. | I12: 3 | K12: =B12 | L12: =IFERROR(AVERAGE(I12:I13),"") | M12: =IFERROR(IF(L12<=1.25,"Sangat Jarang / Tidak Muncul",IF(L12<=2.5,"Kadang-Kadang",IF(L12<=3.75,"Sering Muncul","Konsisten Muncul"))),"")
C13: Kelompok mampu mengaitkan hasil analisis nasabah dengan solusi yang relevan dan sesuai kebutuhan | D13: Solusi yang disampaikan tidak menunjukkan keterkaitan dengan hasil analisis kebutuhan maupun kondisi nasabah. | E13: Kelompok mulai mencoba menghubungkan hasil analisis dengan solusi yang diberikan, namun keterkaitannya masih kurang jelas dan belum sesuai dengan kebutuhan utama nasabah. | F13: Sebagian solusi yang diberikan sudah cukup sesuai dengan hasil analisis dan kebutuhan nasabah, meskipun masih terdapat rekomendasi yang kurang relevan atau kurang spesifik. | G13: Kelompok mampu menghubungkan hasil analisis dengan solusi yang relevan, sesuai kebutuhan, dan mempertimbangkan kondisi nasabah secara cukup menyeluruh. | H13: Kelompok mampu menyusun solusi yang sangat relevan, personal, dan selaras dengan hasil analisis kebutuhan, kondisi, serta prioritas nasabah secara menyeluruh dan terintegrasi. | I13: 3 | K13: =B14 | L13: =IF(I14="","",I14) | M13: =IFERROR(IF(L13<=1.25,"Sangat Jarang / Tidak Muncul",IF(L13<=2.5,"Kadang-Kadang",IF(L13<=3.75,"Sering Muncul","Konsisten Muncul"))),"")
B14: Karsa Mahira: Relevant to Market | C14: Kelompok menunjukkan pemahaman terhadap relevansi layanan dan produk the organization dengan kondisi nasabah dan kebutuhan bisnis saat ini | D14: Kelompok belum mampu menunjukkan keterkaitan antara layanan dan produk the organization dengan kebutuhan nasabah maupun konteks bisnis yang relevan. | E14: Kelompok menunjukkan pemahaman yang terbatas terhadap penggunaan layanan dan produk the organization, sehingga solusi yang diberikan masih kurang sesuai dengan kondisi nasabah. | F14: Kelompok mampu menunjukkan penggunaan layanan dan produk the organization yang cukup relevan dengan kebutuhan dasar nasabah dan konteks bisnis saat ini. | G14: Kelompok menunjukkan pemahaman yang baik terhadap relevansi layanan dan produk the organization dengan kondisi nasabah, serta mampu menjelaskan alasan penggunaan solusi yang dipilih. | H14: Kelompok menunjukkan pemahaman yang kuat dan strategis terhadap layanan dan produk the organization, serta mampu mengaitkannya secara tepat dengan kebutuhan nasabah, peluang bisnis, dan dinamika kebutuhan pasar saat ini. | I14: 3 | K14: =B15 | L14: =IF(I15="","",I15) | M14: =IFERROR(IF(L14<=1.25,"Sangat Jarang / Tidak Muncul",IF(L14<=2.5,"Kadang-Kadang",IF(L14<=3.75,"Sering Muncul","Konsisten Muncul"))),"")
B15: Karsa Tumbuh: Growth Oriented | C15: Kelompok menunjukkan ide atau pendekatan yang adaptif, kreatif, dan relevan dalam penyusunan solusi nasabah | D15: Kelompok tidak menunjukkan adanya ide, pendekatan baru, atau upaya pengembangan solusi dalam penyusunan rekomendasi kepada nasabah. | E15: Kelompok mulai menunjukkan upaya menghadirkan ide atau pendekatan baru, namun masih bersifat umum, kurang relevan, atau belum memberikan nilai tambah yang jelas bagi nasabah. | F15: Kelompok menunjukkan beberapa ide atau pendekatan yang cukup adaptif dan relevan dengan kebutuhan nasabah, meskipun belum sepenuhnya inovatif atau terintegrasi. | G15: Kelompok menunjukkan ide atau pendekatan yang kreatif, relevan, dan mampu menyesuaikan solusi dengan kondisi serta kebutuhan nasabah yang berkembang. | H15: Kelompok menunjukkan kemampuan menghadirkan solusi yang inovatif, adaptif, dan bernilai tambah, melalui pendekatan yang relevan dengan kebutuhan nasabah serta dinamika layanan dan kebutuhan pasar yang terus berkembang. | I15: 4 | K15: =B16 | L15: =IF(I16="","",I16) | M15: =IFERROR(IF(L15<=1.25,"Sangat Jarang / Tidak Muncul",IF(L15<=2.5,"Kadang-Kadang",IF(L15<=3.75,"Sering Muncul","Konsisten Muncul"))),"")
B16: Karsa Satya: Being Sensitive to Risk | C16: Kelompok menunjukkan pertimbangan terhadap potensi risiko dan kesesuaian solusi dalam rekomendasi kepada nasabah | D16: Kelompok tidak menunjukkan pertimbangan terhadap potensi risiko maupun kesesuaian solusi yang direkomendasikan kepada nasabah. | E16: Kelompok mulai menunjukkan perhatian terhadap risiko, namun pertimbangan yang disampaikan masih sangat terbatas dan belum mempertimbangkan kondisi nasabah secara memadai. | F16: Kelompok mampu mengidentifikasi potensi risiko dasar dan menunjukkan pertimbangan terhadap kesesuaian solusi dengan kondisi nasabah. | G16: Kelompok menunjukkan kehati-hatian dan pertimbangan yang jelas terhadap potensi risiko, kesesuaian solusi, serta dampaknya terhadap kondisi nasabah. | H16: Kelompok menunjukkan keberanian dalam mengambil keputusan dan menyusun rekomendasi secara tepat dengan mempertimbangkan potensi risiko, kesesuaian solusi, serta dampaknya terhadap kondisi nasabah, disertai kemampuan menjelaskan risiko yang dapat dikelola dan alasan pengambilan keputusan tersebut. | I16: 4

Sheet Day 1 - 5. Panel Black Box
B2: Day 1: Black Box: Decoding of a Human Life
B4: Cara Pengisian:
B5: Setiap kelompok akan memberikan penilaian pada kelompok lainnya pada 3 kelompok lainnya di ruangan yang sama
B6: Penilaian dilakukan menggunakan skala 1–5 pada setiap aspek yang dinilai.
B7: Berikan penilaian kepada rekan kelompok berdasarkan pengalaman bekerja bersama selama aktivitas berlangsung.
B8: Isi penilaian sesuai perilaku yang benar-benar ditunjukkan peserta dalam proses kerja kelompok.
B9: Berikan penilaian secara objektif dan profesional.
B10: Panduan deskripsi untuk setiap skala penilaian telah disediakan sebagai acuan dalam memberikan nilai.
I11: Score (1-5)
B12: Kompetensi | C12: Item Penilaian | D12: 1 | E12: 2 | F12: 3 | G12: 4 | H12: 5 | I12: KELOMPOK: | K12: Kompetensi | L12: Score | M12: Band (per kegiatan)
B13: Karsa Rasa: Customer First | C13: Kelompok menunjukkan pemahaman yang mendalam terhadap kebutuhan, kondisi, dan prioritas nasabah | D13: Kelompok belum mampu menunjukkan pemahaman terhadap kondisi, kebutuhan, maupun prioritas nasabah. Analisis yang disampaikan masih bersifat umum, tidak relevan, atau tidak didukung informasi dari dokumen dan hasil interaksi dengan nasabah. | E13: Kelompok mulai menunjukkan upaya memahami kondisi nasabah, namun analisis yang disampaikan masih terbatas, kurang mendalam, dan masih didominasi asumsi yang belum terverifikasi. | F13: Kelompok mampu mengidentifikasi kebutuhan dan kondisi utama nasabah berdasarkan informasi yang tersedia, namun pemahaman yang ditunjukkan masih pada level dasar dan belum sepenuhnya menggambarkan prioritas nasabah secara menyeluruh. | G13: Kelompok menunjukkan pemahaman yang baik terhadap kondisi, kebutuhan, dan prioritas nasabah melalui analisis yang relevan dan didukung data atau informasi yang tersedia selama aktivitas dalam presentasi/1-pager | H13: Kelompok menunjukkan pemahaman yang mendalam dan menyeluruh terhadap kebutuhan, kondisi, dan prioritas nasabah, serta mampu menangkap konteks dan pertimbangan penting yang memengaruhi kebutuhan nasabah secara tepat dan relevan. | I13: 3.3333333 | K13: =B13 | L13: =IFERROR(AVERAGE(I13:I14),"") | M13: =IFERROR(IF(L13<=1.25,"Sangat Jarang / Tidak Muncul",IF(L13<=2.5,"Kadang-Kadang",IF(L13<=3.75,"Sering Muncul","Konsisten Muncul"))),"")
C14: Kelompok mampu mengaitkan hasil analisis nasabah dengan solusi yang relevan dan sesuai kebutuhan | D14: Solusi yang disampaikan tidak menunjukkan keterkaitan dengan hasil analisis kebutuhan maupun kondisi nasabah. | E14: Kelompok mulai mencoba menghubungkan hasil analisis dengan solusi yang diberikan, namun keterkaitannya masih kurang jelas dan belum sesuai dengan kebutuhan utama nasabah. | F14: Sebagian solusi yang diberikan sudah cukup sesuai dengan hasil analisis dan kebutuhan nasabah, meskipun masih terdapat rekomendasi yang kurang relevan atau kurang spesifik. | G14: Kelompok mampu menghubungkan hasil analisis dengan solusi yang relevan, sesuai kebutuhan, dan mempertimbangkan kondisi nasabah secara cukup menyeluruh. | H14: Kelompok mampu menyusun solusi yang sangat relevan, personal, dan selaras dengan hasil analisis kebutuhan, kondisi, serta prioritas nasabah secara menyeluruh dan terintegrasi. | I14: 3 | K14: =B15 | L14: =IF(I15="","",I15) | M14: =IFERROR(IF(L14<=1.25,"Sangat Jarang / Tidak Muncul",IF(L14<=2.5,"Kadang-Kadang",IF(L14<=3.75,"Sering Muncul","Konsisten Muncul"))),"")
B15: Karsa Mahira: Relevant to Market | C15: Kelompok menunjukkan pemahaman terhadap relevansi layanan dan produk the organization dengan kondisi nasabah dan kebutuhan bisnis saat ini | D15: Kelompok belum mampu menunjukkan keterkaitan antara layanan dan produk the organization dengan kebutuhan nasabah maupun konteks bisnis yang relevan. | E15: Kelompok menunjukkan pemahaman yang terbatas terhadap penggunaan layanan dan produk the organization, sehingga solusi yang diberikan masih kurang sesuai dengan kondisi nasabah. | F15: Kelompok mampu menunjukkan penggunaan layanan dan produk the organization yang cukup relevan dengan kebutuhan dasar nasabah dan konteks bisnis saat ini. | G15: Kelompok menunjukkan pemahaman yang baik terhadap relevansi layanan dan produk the organization dengan kondisi nasabah, serta mampu menjelaskan alasan penggunaan solusi yang dipilih. | H15: Kelompok menunjukkan pemahaman yang kuat dan strategis terhadap layanan dan produk the organization, serta mampu mengaitkannya secara tepat dengan kebutuhan nasabah, peluang bisnis, dan dinamika kebutuhan pasar saat ini. | I15: 4 | K15: =B16 | L15: =IF(I16="","",I16) | M15: =IFERROR(IF(L15<=1.25,"Sangat Jarang / Tidak Muncul",IF(L15<=2.5,"Kadang-Kadang",IF(L15<=3.75,"Sering Muncul","Konsisten Muncul"))),"")
B16: Karsa Tumbuh: Growth Oriented | C16: Kelompok menunjukkan ide atau pendekatan yang adaptif, kreatif, dan relevan dalam penyusunan solusi nasabah | D16: Kelompok tidak menunjukkan adanya ide, pendekatan baru, atau upaya pengembangan solusi dalam penyusunan rekomendasi kepada nasabah. | E16: Kelompok mulai menunjukkan upaya menghadirkan ide atau pendekatan baru, namun masih bersifat umum, kurang relevan, atau belum memberikan nilai tambah yang jelas bagi nasabah. | F16: Kelompok menunjukkan beberapa ide atau pendekatan yang cukup adaptif dan relevan dengan kebutuhan nasabah, meskipun belum sepenuhnya inovatif atau terintegrasi. | G16: Kelompok menunjukkan ide atau pendekatan yang kreatif, relevan, dan mampu menyesuaikan solusi dengan kondisi serta kebutuhan nasabah yang berkembang. | H16: Kelompok menunjukkan kemampuan menghadirkan solusi yang inovatif, adaptif, dan bernilai tambah, melalui pendekatan yang relevan dengan kebutuhan nasabah serta dinamika layanan dan kebutuhan pasar yang terus berkembang. | I16: 3 | K16: =B17 | L16: =IF(I17="","",I17) | M16: =IFERROR(IF(L16<=1.25,"Sangat Jarang / Tidak Muncul",IF(L16<=2.5,"Kadang-Kadang",IF(L16<=3.75,"Sering Muncul","Konsisten Muncul"))),"")
B17: Karsa Satya: Being Sensitive to Risk | C17: Kelompok menunjukkan pertimbangan terhadap potensi risiko dan kesesuaian solusi dalam rekomendasi kepada nasabah | D17: Kelompok tidak menunjukkan pertimbangan terhadap potensi risiko maupun kesesuaian solusi yang direkomendasikan kepada nasabah. | E17: Kelompok mulai menunjukkan perhatian terhadap risiko, namun pertimbangan yang disampaikan masih sangat terbatas dan belum mempertimbangkan kondisi nasabah secara memadai. | F17: Kelompok mampu mengidentifikasi potensi risiko dasar dan menunjukkan pertimbangan terhadap kesesuaian solusi dengan kondisi nasabah. | G17: Kelompok menunjukkan kehati-hatian dan pertimbangan yang jelas terhadap potensi risiko, kesesuaian solusi, serta dampaknya terhadap kondisi nasabah. | H17: Kelompok menunjukkan keberanian dalam mengambil keputusan dan menyusun rekomendasi secara tepat dengan mempertimbangkan potensi risiko, kesesuaian solusi, serta dampaknya terhadap kondisi nasabah, disertai kemampuan menjelaskan risiko yang dapat dikelola dan alasan pengambilan keputusan tersebut. | I17: 4

Sheet Day 1 - 6. Assignment
B2: Day 1: Solo Transmission: The Ascendant’s Stand
B4: Cara Pengisian:
B5: Penilaian dilakukan menggunakan skala 1–5 pada setiap aspek yang dinilai.
B6: Tonton keseluruhan video dan worksheet peserta sebelum memberikan penilaian.
B7: Berikan penilaian berdasarkan isi dan penyampaian yang ditampilkan dalam video dan worksheet
B8: Panduan deskripsi untuk setiap skala penilaian telah disediakan sebagai acuan dalam memberikan nilai.
B10: Aspek Penilaian | C10: Item Penilaian | D10: 1 | E10: 2 | F10: 3 | G10: 4 | H10: 5 | I10: Score | K10: Kompetensi | L10: Score
B11: Penilaian Worksheet | K11: WORKSHEET | M11: Band (per kegiatan)
B12: Karsa Rasa: Building Partnership | C12: Peserta menunjukkan pemahaman terhadap potensi, performa, dan kebutuhan pengembangan masing-masing anggota tim dalam penyusunan 9-Grid Talent Matrix | D12: Pemetaan anggota tim tidak menunjukkan pemahaman terhadap potensi maupun performa individu, serta tidak didukung pertimbangan yang relevan. | E12: Pemetaan anggota tim mulai menunjukkan pertimbangan terhadap potensi dan performa individu, namun masih sangat umum dan belum menggambarkan kebutuhan pengembangan masing-masing anggota tim. | F12: Pemetaan anggota tim cukup menggambarkan potensi, performa, dan kebutuhan pengembangan individu, meskipun masih terdapat beberapa analisis yang kurang mendalam atau kurang konsisten. | G12: Pemetaan anggota tim menunjukkan pemahaman yang jelas terhadap potensi, performa, dan kebutuhan pengembangan masing-masing individu dengan pertimbangan yang relevan. | H12: Pemetaan anggota tim menunjukkan pemahaman yang mendalam dan menyeluruh terhadap potensi, performa, karakteristik, dan kebutuhan pengembangan masing-masing individu secara objektif dan relevan. | I12: 4 | K12: =B12 | L12: =IFERROR(AVERAGE(I12:I13),"") | M12: =IFERROR(IF(L12<=1.25,"Sangat Jarang / Tidak Muncul",IF(L12<=2.5,"Kadang-Kadang",IF(L12<=3.75,"Sering Muncul","Konsisten Muncul"))),"")
C13: Peserta menyusun objective dan action plan yang relevan dengan kebutuhan masing-masing anggota tim serta mendukung perkembangan individu dan tim | D13: Objective dan action plan yang disusun tidak relevan dengan kebutuhan pengembangan anggota tim dan tidak menunjukkan arah pengembangan yang jelas. | E13: Objective dan action plan mulai menunjukkan upaya pengembangan individu, namun masih umum, kurang spesifik, dan belum sesuai dengan kebutuhan masing-masing anggota tim. | F13: Objective dan action plan cukup relevan dengan kebutuhan pengembangan individu, namun masih terdapat beberapa bagian yang belum spesifik atau belum terintegrasi dengan kebutuhan tim. | G13: Objective dan action plan disusun secara jelas, relevan, dan sesuai dengan kebutuhan pengembangan individu maupun tim. | H13: Objective dan action plan disusun secara sangat jelas, spesifik, terarah, dan menunjukkan pemahaman yang kuat terhadap kebutuhan pengembangan individu serta kontribusinya terhadap perkembangan tim. | I13: 3 | K13: =B14 | L13: =IF(I14="","",I14) | M13: =IFERROR(IF(L13<=1.25,"Sangat Jarang / Tidak Muncul",IF(L13<=2.5,"Kadang-Kadang",IF(L13<=3.75,"Sering Muncul","Konsisten Muncul"))),"")
B14: Karsa Mahira: Relevant to Market | C14: Peserta menyusun pengembangan anggota tim yang relevan dengan kebutuhan peran, tantangan bisnis, dan kompetensi yang dibutuhkan the organization | D14: Rencana pengembangan yang disusun tidak relevan dengan kebutuhan peran maupun kompetensi yang dibutuhkan organisasi. | E14: Rencana pengembangan mulai menunjukkan keterkaitan dengan kebutuhan peran, namun masih umum dan belum mempertimbangkan kebutuhan bisnis atau kompetensi yang relevan. | F14: Rencana pengembangan cukup relevan dengan kebutuhan peran dan kompetensi individu, meskipun belum sepenuhnya mempertimbangkan kebutuhan bisnis the organization secara menyeluruh. | G14: Rencana pengembangan relevan dengan kebutuhan peran, tantangan bisnis, dan kompetensi yang dibutuhkan the organization saat ini. | H14: Rencana pengembangan menunjukkan pemahaman yang kuat terhadap kebutuhan talenta the organization, tantangan bisnis, serta kompetensi masa depan yang diperlukan organisasi secara strategis dan relevan. | I14: 4
B15: Penilaian Video | K15: VIDEO
B16: Karsa Daya: GRIT | C16: Peserta menyelesaikan dan mengumpulkan seluruh tugas sesuai waktu yang ditentukan | D16: Tugas tidak dikumpulkan sesuai waktu yang ditentukan | E16: - | F16: - | G16: - | H16: Tugas dikumpulkan sesuai waktu yang ditentukan | I16: 5 | K16: =B16 | L16: =IF(I16="","",I16) | M16: =IFERROR(IF(L16<=1.25,"Sangat Jarang / Tidak Muncul",IF(L16<=2.5,"Kadang-Kadang",IF(L16<=3.75,"Sering Muncul","Konsisten Muncul"))),"")
B17: Karsa Daya: Navigating Agility | C17: Peserta mampu menjelaskan keputusan kepemimpinan dengan mempertimbangkan dinamika tim dan tantangan yang dihadapi dalam case study | D17: Penjelasan keputusan tidak mempertimbangkan dinamika tim maupun tantangan yang terdapat dalam case study. | E17: Peserta mulai mempertimbangkan kondisi tim dan tantangan yang ada, namun penjelasan yang diberikan masih terbatas dan kurang relevan. | F17: Peserta cukup mampu menjelaskan keputusan dengan mempertimbangkan beberapa dinamika tim dan tantangan yang dihadapi. | G17: Peserta mampu menjelaskan keputusan secara relevan dengan mempertimbangkan dinamika tim, kondisi individu, dan tantangan dalam case study. | H17: Peserta menunjukkan kemampuan yang sangat baik dalam menyesuaikan keputusan kepemimpinan terhadap dinamika tim, tantangan situasi, dan kebutuhan organisasi secara tepat dan adaptif. | I17: 4 | K17: =B17 | L17: =IF(I17="","",I17) | M17: =IFERROR(IF(L17<=1.25,"Sangat Jarang / Tidak Muncul",IF(L17<=2.5,"Kadang-Kadang",IF(L17<=3.75,"Sering Muncul","Konsisten Muncul"))),"")
B18: Karsa Jaya: Excellence in Execution | C18: Peserta menyampaikan penjelasan secara jelas, terstruktur, dan meyakinkan dalam video yang dibuat | D18: Penjelasan dalam video tidak jelas, tidak terstruktur, dan sulit dipahami. | E18: Penjelasan dalam video mulai menunjukkan alur yang cukup jelas, namun masih kurang terstruktur dan kurang meyakinkan. | F18: Penjelasan dalam video cukup jelas dan terstruktur, meskipun masih terdapat beberapa bagian yang kurang kuat atau kurang konsisten. | G18: Penjelasan dalam video disampaikan secara jelas, terstruktur, dan mampu mendukung pemahaman terhadap keputusan yang diambil. | H18: Penjelasan dalam video disampaikan secara sangat jelas, sistematis, meyakinkan, dan menunjukkan kemampuan eksekusi komunikasi yang kuat terhadap stakeholder. | I18: 4 | K18: =B18 | L18: =IF(I18="","",I18) | M18: =IFERROR(IF(L18<=1.25,"Sangat Jarang / Tidak Muncul",IF(L18<=2.5,"Kadang-Kadang",IF(L18<=3.75,"Sering Muncul","Konsisten Muncul"))),"")

Sheet Day 1 - Rekap (Auto)
B2: DAY 1 — KONTRIBUSI KE SKOR TOTAL
B3: Peserta: | C3: ='REKAP TOTAL (Auto)'!C3 | E3: Kontribusi = poin yang hari ini sumbang ke skor Karsa di Rekap 3 Hari
E5: NILAI KEGIATAN HARI INI (0–100)
B6: Kompetensi | C6: Kontribusi hari ini (poin) | D6: Launchpad | E6: Talkshow | F6: Mission | G6: Black Box | H6: Indiv Assignment | I6: BB Panel | J6: BB Peer | K6: Uraian (diisi asesor)
