Workbook

Sheet Panduan
A1: PANDUAN PENGGUNAAN MENTORING TRACKER
A2: Gunakan Dashboard untuk ringkasan, Scorecard ToC untuk capaian Output–Outcome–Impact, Tracker ToC untuk pembaruan indikator, Rantai ToC untuk logika perubahan, Blueprint Program untuk katalog target client, dan Data Sumber untuk audit. | B2: Gunakan Dashboard untuk ringkasan, Scorecard ToC untuk capaian Output–Outcome–Impact, Tracker ToC untuk pembaruan indikator, Rantai ToC untuk logika perubahan, Blueprint Program untuk katalog target client, dan Data Sumber untuk audit. | C2: Gunakan Dashboard untuk ringkasan, Scorecard ToC untuk capaian Output–Outcome–Impact, Tracker ToC untuk pembaruan indikator, Rantai ToC untuk logika perubahan, Blueprint Program untuk katalog target client, dan Data Sumber untuk audit. | D2: Gunakan Dashboard untuk ringkasan, Scorecard ToC untuk capaian Output–Outcome–Impact, Tracker ToC untuk pembaruan indikator, Rantai ToC untuk logika perubahan, Blueprint Program untuk katalog target client, dan Data Sumber untuk audit. | E2: Gunakan Dashboard untuk ringkasan, Scorecard ToC untuk capaian Output–Outcome–Impact, Tracker ToC untuk pembaruan indikator, Rantai ToC untuk logika perubahan, Blueprint Program untuk katalog target client, dan Data Sumber untuk audit. | F2: Gunakan Dashboard untuk ringkasan, Scorecard ToC untuk capaian Output–Outcome–Impact, Tracker ToC untuk pembaruan indikator, Rantai ToC untuk logika perubahan, Blueprint Program untuk katalog target client, dan Data Sumber untuk audit. | G2: Gunakan Dashboard untuk ringkasan, Scorecard ToC untuk capaian Output–Outcome–Impact, Tracker ToC untuk pembaruan indikator, Rantai ToC untuk logika perubahan, Blueprint Program untuk katalog target client, dan Data Sumber untuk audit. | H2: Gunakan Dashboard untuk ringkasan, Scorecard ToC untuk capaian Output–Outcome–Impact, Tracker ToC untuk pembaruan indikator, Rantai ToC untuk logika perubahan, Blueprint Program untuk katalog target client, dan Data Sumber untuk audit.
A3: Gunakan Dashboard untuk ringkasan, Scorecard ToC untuk capaian Output–Outcome–Impact, Tracker ToC untuk pembaruan indikator, Rantai ToC untuk logika perubahan, Blueprint Program untuk katalog target client, dan Data Sumber untuk audit. | B3: Gunakan Dashboard untuk ringkasan, Scorecard ToC untuk capaian Output–Outcome–Impact, Tracker ToC untuk pembaruan indikator, Rantai ToC untuk logika perubahan, Blueprint Program untuk katalog target client, dan Data Sumber untuk audit. | C3: Gunakan Dashboard untuk ringkasan, Scorecard ToC untuk capaian Output–Outcome–Impact, Tracker ToC untuk pembaruan indikator, Rantai ToC untuk logika perubahan, Blueprint Program untuk katalog target client, dan Data Sumber untuk audit. | D3: Gunakan Dashboard untuk ringkasan, Scorecard ToC untuk capaian Output–Outcome–Impact, Tracker ToC untuk pembaruan indikator, Rantai ToC untuk logika perubahan, Blueprint Program untuk katalog target client, dan Data Sumber untuk audit. | E3: Gunakan Dashboard untuk ringkasan, Scorecard ToC untuk capaian Output–Outcome–Impact, Tracker ToC untuk pembaruan indikator, Rantai ToC untuk logika perubahan, Blueprint Program untuk katalog target client, dan Data Sumber untuk audit. | F3: Gunakan Dashboard untuk ringkasan, Scorecard ToC untuk capaian Output–Outcome–Impact, Tracker ToC untuk pembaruan indikator, Rantai ToC untuk logika perubahan, Blueprint Program untuk katalog target client, dan Data Sumber untuk audit. | G3: Gunakan Dashboard untuk ringkasan, Scorecard ToC untuk capaian Output–Outcome–Impact, Tracker ToC untuk pembaruan indikator, Rantai ToC untuk logika perubahan, Blueprint Program untuk katalog target client, dan Data Sumber untuk audit. | H3: Gunakan Dashboard untuk ringkasan, Scorecard ToC untuk capaian Output–Outcome–Impact, Tracker ToC untuk pembaruan indikator, Rantai ToC untuk logika perubahan, Blueprint Program untuk katalog target client, dan Data Sumber untuk audit.
A5: 1. Aturan Data
A6: Aturan | B6: Penjelasan | D6: Langkah | E6: Pertanyaan Mentor | F6: Bukti Minimum | G6: Keputusan | H6: Pemilik
A7: Data laporan | B7: Angka yang terbaca langsung dari Laporan Change Report, Process, Blueprint. Sumber realisasi = Laporan. | D7: 1. Validasi Input | E7: Apakah sumber daya benar-benar tersedia? | F7: Pagu, realisasi, daftar personel | G7: Lanjut/eskalasi hambatan | H7: PIC Program
A8: Turunan laporan | B8: Angka yang diturunkan secara transparan dari konteks laporan, bukan angka eksplisit pada kalimat indikator. | D8: 2. Cek Activity | E8: Apakah kegiatan terlaksana sesuai desain? | F8: Jadwal, daftar hadir, dokumentasi | G8: Perbaiki cakupan/kualitas | H8: PIC Kegiatan
A9: Data dummy | B9: Nilai sementara untuk baseline, target, atau metrik baru yang belum ada. Sel angkanya diberi warna merah muda. | D9: 3. Verifikasi Output | E9: Apa yang benar-benar dihasilkan dan siapa yang dijangkau? | F9: Rekap lokasi, peserta, media | G9: Rekonsiliasi angka | H9: Admin Data
A10: Ganti data dummy | B10: Tim program wajib mengganti sel merah muda setelah bukti tersedia dan mengubah kolom sumber menjadi Laporan/Turunan. | D10: 4. Uji Outcome | E10: Apakah pengetahuan/perilaku berubah? | F10: Pre/post-test, survei, hasil inspeksi | G10: Pertahankan/adaptasi intervensi | H10: M&E
A11: Jangan menafsirkan dummy sebagai hasil | B11: Dashboard mencampurkan data sumber dan dummy; gunakan filter Kualitas Data sebelum mengambil keputusan eksternal. | D11: 5. Tinjau Impact | E11: Apakah hasil jangka panjang membaik dan apa kontribusi program? | F11: Data insiden, tren, pembanding | G11: Lanjutkan, ubah, atau hentikan | H11: Pimpinan Program
A13: 3. Definisi Status
A14: Status | B14: Definisi | D14: • Laporan sumber berfokus pada aktivitas/output; baseline, target numerik, Outcome, dan Impact umumnya belum tersedia.
A15: Tercapai | B15: Capaian ≥ 100% | D15: • Nilai X pada A7 belum diisi; tracker memakai dummy agar formula dan alur monitoring dapat diuji.
A16: In Progress | B16: Capaian 80%–99,9% | D16: • Keterangan 'semua loket' pada A4 diturunkan menjadi 8 loket berdasarkan cakupan keluaran lain dan harus dikonfirmasi.
A17: Perlu Perhatian | B17: Capaian < 80% | D17: • Persentase capaian tidak membuktikan kausalitas. Impact perlu data pembanding dan evaluasi kontribusi.
A18: Belum Ada Data | B18: Realisasi belum tersedia atau belum jatuh tempo | D18: • Workbook dibuat dalam Bahasa Indonesia untuk rapat mentoring internal dan belum menjadi laporan publik.

Sheet Dashboard
A1: DASHBOARD MENTORING – JAWA TIMUR
A2: Ringkasan Juni 2026 | 12 program | Target Output/Outcome: Key Activity Breakdown | Target Impact: Strategic Alignment | Data dummy ditandai merah muda. | B2: Ringkasan Juni 2026 | 12 program | Target Output/Outcome: Key Activity Breakdown | Target Impact: Strategic Alignment | Data dummy ditandai merah muda. | C2: Ringkasan Juni 2026 | 12 program | Target Output/Outcome: Key Activity Breakdown | Target Impact: Strategic Alignment | Data dummy ditandai merah muda. | D2: Ringkasan Juni 2026 | 12 program | Target Output/Outcome: Key Activity Breakdown | Target Impact: Strategic Alignment | Data dummy ditandai merah muda. | E2: Ringkasan Juni 2026 | 12 program | Target Output/Outcome: Key Activity Breakdown | Target Impact: Strategic Alignment | Data dummy ditandai merah muda. | F2: Ringkasan Juni 2026 | 12 program | Target Output/Outcome: Key Activity Breakdown | Target Impact: Strategic Alignment | Data dummy ditandai merah muda. | G2: Ringkasan Juni 2026 | 12 program | Target Output/Outcome: Key Activity Breakdown | Target Impact: Strategic Alignment | Data dummy ditandai merah muda. | H2: Ringkasan Juni 2026 | 12 program | Target Output/Outcome: Key Activity Breakdown | Target Impact: Strategic Alignment | Data dummy ditandai merah muda. | I2: Ringkasan Juni 2026 | 12 program | Target Output/Outcome: Key Activity Breakdown | Target Impact: Strategic Alignment | Data dummy ditandai merah muda. | J2: Ringkasan Juni 2026 | 12 program | Target Output/Outcome: Key Activity Breakdown | Target Impact: Strategic Alignment | Data dummy ditandai merah muda. | K2: Ringkasan Juni 2026 | 12 program | Target Output/Outcome: Key Activity Breakdown | Target Impact: Strategic Alignment | Data dummy ditandai merah muda.
A4: Program | D4: Indikator | G4: Rata-rata Capaian | J4: Mengandung Dummy
A5: =COUNTA('Blueprint Program'!A6:A17) -> 12 | D5: =COUNTA('Tracker ToC'!A8:A78) -> 71 | G5: =AVERAGE('Tracker ToC'!M8:M78) -> 0.74349127 | J5: =COUNTIF('Tracker ToC'!V8:V78,"Mengandung Dummy") -> 71
A8: Status Indikator | D8: Kualitas Realisasi
A9: Status | B9: Jumlah | D9: Sumber Realisasi | E9: Jumlah
A10: Tercapai | B10: =COUNTIF('Tracker ToC'!N8:N78,"Tercapai") -> 18 | D10: Laporan | E10: =COUNTIF('Tracker ToC'!U8:U78,"Laporan") -> 16
A11: In Progress | B11: =COUNTIF('Tracker ToC'!N8:N78,"In Progress") -> 17 | D11: Turunan | E11: =COUNTIF('Tracker ToC'!U8:U78,"Turunan") -> 1
A12: Perlu Perhatian | B12: =COUNTIF('Tracker ToC'!N8:N78,"Perlu Perhatian") -> 36 | D12: Dummy | E12: =COUNTIF('Tracker ToC'!U8:U78,"Dummy") -> 54
A13: Belum Ada Data | B13: =COUNTIF('Tracker ToC'!N8:N78,"Belum Ada Data") -> 0
A15: Tingkat ToC | B15: Rata-rata Capaian
A16: Input | B16: =IFERROR(AVERAGEIF('Tracker ToC'!E8:E78,A16,'Tracker ToC'!M8:M78),0) -> 0.7648082
A17: Activity | B17: =IFERROR(AVERAGEIF('Tracker ToC'!E9:E79,A17,'Tracker ToC'!M9:M79),0) -> 0.73177083
A18: Output | B18: =IFERROR(AVERAGEIF('Tracker ToC'!E10:E80,A18,'Tracker ToC'!M10:M80),0) -> 0.81578947
A19: Outcome | B19: =IFERROR(AVERAGEIF('Tracker ToC'!E11:E81,A19,'Tracker ToC'!M11:M81),0) -> 0.76275327
A20: Impact | B20: =IFERROR(AVERAGEIF('Tracker ToC'!E12:E82,A20,'Tracker ToC'!M12:M82),0) -> 0.60406746
A23: Prioritas Mentoring
A24: 1 | B24: Ganti seluruh sel merah muda dengan data yang terverifikasi.
A25: 2 | B25: Tetapkan target numerik berbasis baseline dan kapasitas program.
A26: 3 | B26: Mulai pre/post-test untuk A3, A4, A5, dan penilaian simulasi untuk A6.
A27: 4 | B27: Buat register tindak lanjut kolaborasi untuk A7.

Sheet Tracker ToC
A1: MENTORING TRACKER – THEORY OF CHANGE
A2: Periode laporan: Juni 2026 | Sel merah muda = data dummy yang wajib diganti | Persentase capaian dihitung dari Realisasi ÷ Target.
A5: Filter berdasarkan program, tingkat ToC, status, atau kualitas data. Outcome dan Impact disarankan divalidasi melalui survei/administrative data.
A7: ID | B7: Periode | C7: Kode | D7: Program | E7: Tingkat ToC | F7: Pernyataan Hasil/Kegiatan | G7: Indikator | H7: Definisi Operasional | I7: Baseline | J7: Target | K7: Realisasi | L7: Satuan | M7: % Capaian | N7: Status | O7: Bukti/Sumber | P7: Frekuensi | Q7: PIC | R7: Tindak Lanjut Mentoring | S7: Sumber Baseline | T7: Sumber Target | U7: Sumber Realisasi | V7: Kualitas Data | W7: Catatan
A8: IND-001 | B8: 46203 | C8: A1 | D8: Road Safety Baseline Study & Data Mapping | E8: Input | F8: Data dan sumber daya studi baseline tersedia | G8: Ketersediaan sumber data baseline | H8: Jumlah set data utama yang siap dianalisis | I8: 0 | J8: 3 | K8: 2 | L8: set data | M8: =IFERROR(K8/J8,0) -> 0.66666667 | N8: =IF(K8="","Belum Ada Data",IF(M8>=1,"Tercapai",IF(M8>=0.8,"In Progress","Perlu Perhatian"))) -> Perlu Perhatian | O8: Blueprint 6.jpeg – A1 | P8: Bulanan | Q8: Change Agent, Change Booster, Sub Bagian Pelayanan | R8: Konfirmasi kelengkapan data korban, santunan, dan faktor penyebab | S8: Dummy | T8: Blueprint | U8: Dummy | V8: =IF(OR(S8="Dummy",T8="Dummy",U8="Dummy"),"Mengandung Dummy",IF(OR(S8="Turunan",T8="Turunan",U8="Turunan"),"Turunan Laporan","Laporan")) -> Mengandung Dummy
A9: IND-002 | B9: 46203 | C9: A1 | D9: Road Safety Baseline Study & Data Mapping | E9: Activity | F9: Studi baseline dan pemetaan dilaksanakan | G9: Tahapan studi baseline selesai | H9: Proporsi tahapan studi yang selesai | I9: 0 | J9: 1 | K9: 0.75 | L9: % tahapan | M9: =IFERROR(K9/J9,0) -> 0.75 | N9: =IF(K9="","Belum Ada Data",IF(M9>=1,"Tercapai",IF(M9>=0.8,"In Progress","Perlu Perhatian"))) -> Perlu Perhatian | O9: Blueprint 6.jpeg – A1 | P9: Bulanan | Q9: Change Agent, Change Booster, Sub Bagian Pelayanan | R9: Lampirkan metodologi, daftar data, dan notulen penyamaan persepsi | S9: Dummy | T9: Blueprint | U9: Dummy | V9: =IF(OR(S9="Dummy",T9="Dummy",U9="Dummy"),"Mengandung Dummy",IF(OR(S9="Turunan",T9="Turunan",U9="Turunan"),"Turunan Laporan","Laporan")) -> Mengandung Dummy
A10: IND-003 | B10: 46203 | C10: A1 | D10: Road Safety Baseline Study & Data Mapping | E10: Output | F10: Road safety insight report; data korban kecelakaan dan santunan; faktor penyebab kecelakaan. | G10: Deliverable baseline tersedia | H10: Jumlah deliverable yang tersedia: insight report, data korban/santunan, dan faktor penyebab | I10: 0 | J10: 3 | K10: 2 | L10: deliverable | M10: =IFERROR(K10/J10,0) -> 0.66666667 | N10: =IF(K10="","Belum Ada Data",IF(M10>=1,"Tercapai",IF(M10>=0.8,"In Progress","Perlu Perhatian"))) -> Perlu Perhatian | O10: Blueprint 6.jpeg – A1 | P10: Bulanan | Q10: Change Agent, Change Booster, Sub Bagian Pelayanan | R10: Validasi tiga deliverable dan tautan penyimpanan | S10: Dummy | T10: Blueprint | U10: Dummy | V10: =IF(OR(S10="Dummy",T10="Dummy",U10="Dummy"),"Mengandung Dummy",IF(OR(S10="Turunan",T10="Turunan",U10="Turunan"),"Turunan Laporan","Laporan")) -> Mengandung Dummy | W10: Target naratif: Key Activity Breakdown 6.jpeg.
A11: IND-004 | B11: 46203 | C11: A1 | D11: Road Safety Baseline Study & Data Mapping | E11: Outcome | F11: Tersedianya data kecelakaan sebagai dasar Program JAWA TIMUR dan setiap intervensi JAWA TIMUR berbasis data. | G11: Intervensi yang menggunakan baseline | H11: Persentase intervensi yang merujuk pada baseline atau dashboard | I11: 0 | J11: 1 | K11: 0.7 | L11: % intervensi | M11: =IFERROR(K11/J11,0) -> 0.7 | N11: =IF(K11="","Belum Ada Data",IF(M11>=1,"Tercapai",IF(M11>=0.8,"In Progress","Perlu Perhatian"))) -> Perlu Perhatian | O11: Blueprint 6.jpeg – A1 | P11: Triwulanan | Q11: Change Agent, Change Booster, Sub Bagian Pelayanan | R11: Tambahkan referensi baseline pada setiap proposal intervensi | S11: Dummy | T11: Blueprint | U11: Dummy | V11: =IF(OR(S11="Dummy",T11="Dummy",U11="Dummy"),"Mengandung Dummy",IF(OR(S11="Turunan",T11="Turunan",U11="Turunan"),"Turunan Laporan","Laporan")) -> Mengandung Dummy | W11: Target naratif: Key Activity Breakdown 6.jpeg.
A12: IND-005 | B12: 46203 | C12: A1 | D12: Road Safety Baseline Study & Data Mapping | E12: Impact | F12: Implementasi Penanganan Titik Rawan Laka 100% terintervensi (Data & Digital) | G12: Rekomendasi berbasis data ditindaklanjuti | H12: Persentase rekomendasi berbasis data yang ditindaklanjuti | I12: 0 | J12: 0.8 | K12: 0.6 | L12: % rekomendasi | M12: =IFERROR(K12/J12,0) -> 0.75 | N12: =IF(K12="","Belum Ada Data",IF(M12>=1,"Tercapai",IF(M12>=0.8,"In Progress","Perlu Perhatian"))) -> Perlu Perhatian | O12: Blueprint 6.jpeg – A1 | P12: Semesteran | Q12: Change Agent, Change Booster, Sub Bagian Pelayanan | R12: Buat register rekomendasi dan keputusan | S12: Dummy | T12: Dummy | U12: Dummy | V12: =IF(OR(S12="Dummy",T12="Dummy",U12="Dummy"),"Mengandung Dummy",IF(OR(S12="Turunan",T12="Turunan",U12="Turunan"),"Turunan Laporan","Laporan")) -> Mengandung Dummy | W12: Target naratif: Strategic Alignment 2.jpeg. Pemetaan impact perlu konfirmasi klien; skor memakai indikator impact Tracker sebagai proxy sampai KPI strategis diisi.
A13: IND-006 | B13: 46203 | C13: A2 | D13: Blackspot Intervention Program | E13: Input | F13: Sumber daya intervensi blackspot tersedia | G13: Anggaran intervensi tersedia | H13: Anggaran yang dialokasikan dan direalisasikan | I13: 0 | J13: 25 | K13: 20 | L13: Rp juta | M13: =IFERROR(K13/J13,0) -> 0.8 | N13: =IF(K13="","Belum Ada Data",IF(M13>=1,"Tercapai",IF(M13>=0.8,"In Progress","Perlu Perhatian"))) -> In Progress | O13: Blueprint 6.jpeg – A2 | P13: Bulanan | Q13: Sub Bagian Pelayanan | R13: Konfirmasi pagu dan dukungan stakeholder | S13: Dummy | T13: Dummy | U13: Dummy | V13: =IF(OR(S13="Dummy",T13="Dummy",U13="Dummy"),"Mengandung Dummy",IF(OR(S13="Turunan",T13="Turunan",U13="Turunan"),"Turunan Laporan","Laporan")) -> Mengandung Dummy
A14: IND-007 | B14: 46203 | C14: A2 | D14: Blackspot Intervention Program | E14: Activity | F14: Intervensi titik rawan dirancang dan dilaksanakan | G14: Tahapan intervensi selesai | H14: Proporsi tahapan pemetaan, koordinasi, dan intervensi yang selesai | I14: 0 | J14: 1 | K14: 0.8 | L14: % tahapan | M14: =IFERROR(K14/J14,0) -> 0.8 | N14: =IF(K14="","Belum Ada Data",IF(M14>=1,"Tercapai",IF(M14>=0.8,"In Progress","Perlu Perhatian"))) -> In Progress | O14: Blueprint 6.jpeg – A2 | P14: Bulanan | Q14: Sub Bagian Pelayanan | R14: Lampirkan peta titik rawan dan berita acara koordinasi | S14: Dummy | T14: Blueprint | U14: Dummy | V14: =IF(OR(S14="Dummy",T14="Dummy",U14="Dummy"),"Mengandung Dummy",IF(OR(S14="Turunan",T14="Turunan",U14="Turunan"),"Turunan Laporan","Laporan")) -> Mengandung Dummy
A15: IND-008 | B15: 46203 | C15: A2 | D15: Blackspot Intervention Program | E15: Output | F15: Rekomendasi kegiatan atau intervensi berdasarkan pemetaan, seperti rambu, edukasi, dan intervensi relevan lainnya. | G15: Rekomendasi intervensi berbasis pemetaan | H15: Jumlah dokumen rekomendasi kegiatan/intervensi | I15: 0 | J15: 1 | K15: 1 | L15: dokumen | M15: =IFERROR(K15/J15,0) -> 1 | N15: =IF(K15="","Belum Ada Data",IF(M15>=1,"Tercapai",IF(M15>=0.8,"In Progress","Perlu Perhatian"))) -> Tercapai | O15: Blueprint 6.jpeg – A2 | P15: Bulanan | Q15: Sub Bagian Pelayanan | R15: Catat jenis intervensi, lokasi, PIC, dan tenggat | S15: Dummy | T15: Blueprint | U15: Dummy | V15: =IF(OR(S15="Dummy",T15="Dummy",U15="Dummy"),"Mengandung Dummy",IF(OR(S15="Turunan",T15="Turunan",U15="Turunan"),"Turunan Laporan","Laporan")) -> Mengandung Dummy | W15: Target naratif: Key Activity Breakdown 6.jpeg.
A16: IND-009 | B16: 46203 | C16: A2 | D16: Blackspot Intervention Program | E16: Outcome | F16: Stakeholder melakukan intervensi pada titik rawan dan koordinasi lintas lembaga meningkat. | G16: Titik rawan dengan intervensi stakeholder | H16: Jumlah titik rawan yang menerima intervensi | I16: 0 | J16: 3 | K16: 2 | L16: titik rawan | M16: =IFERROR(K16/J16,0) -> 0.66666667 | N16: =IF(K16="","Belum Ada Data",IF(M16>=1,"Tercapai",IF(M16>=0.8,"In Progress","Perlu Perhatian"))) -> Perlu Perhatian | O16: Blueprint 6.jpeg – A2 | P16: Triwulanan | Q16: Sub Bagian Pelayanan | R16: Ganti angka dummy dengan bukti intervensi per lokasi | S16: Dummy | T16: Dummy | U16: Dummy | V16: =IF(OR(S16="Dummy",T16="Dummy",U16="Dummy"),"Mengandung Dummy",IF(OR(S16="Turunan",T16="Turunan",U16="Turunan"),"Turunan Laporan","Laporan")) -> Mengandung Dummy | W16: Target naratif: Key Activity Breakdown 6.jpeg.
A17: IND-010 | B17: 46203 | C17: A2 | D17: Blackspot Intervention Program | E17: Impact | F17: Implementasi Penanganan Titik Rawan Laka 100% terintervensi (Data & Digital) | G17: Penurunan insiden pada titik intervensi | H17: Persentase penurunan insiden dibanding periode pembanding | I17: 0 | J17: 0.1 | K17: 0.04 | L17: % penurunan | M17: =IFERROR(K17/J17,0) -> 0.4 | N17: =IF(K17="","Belum Ada Data",IF(M17>=1,"Tercapai",IF(M17>=0.8,"In Progress","Perlu Perhatian"))) -> Perlu Perhatian | O17: Blueprint 6.jpeg – A2 | P17: Semesteran | Q17: Sub Bagian Pelayanan | R17: Gunakan data sebelum–sesudah dan lokasi pembanding | S17: Dummy | T17: Dummy | U17: Dummy | V17: =IF(OR(S17="Dummy",T17="Dummy",U17="Dummy"),"Mengandung Dummy",IF(OR(S17="Turunan",T17="Turunan",U17="Turunan"),"Turunan Laporan","Laporan")) -> Mengandung Dummy | W17: Target naratif: Strategic Alignment 2.jpeg. Pemetaan impact perlu konfirmasi klien; skor memakai indikator impact Tracker sebagai proxy sampai KPI strategis diisi.
A18: IND-011 | B18: 46203 | C18: A3 | D18: Road Safety Education Program | E18: Input | F18: Sumber daya edukasi sekolah tersedia | G18: Anggaran program tersedia | H18: Anggaran yang dialokasikan dan direalisasikan untuk edukasi sekolah | I18: 0 | J18: 50 | K18: 42 | L18: Rp juta | M18: =IFERROR(K18/J18,0) -> 0.84 | N18: =IF(K18="","Belum Ada Data",IF(M18>=1,"Tercapai",IF(M18>=0.8,"In Progress","Perlu Perhatian"))) -> In Progress | O18: Belum ada di laporan | P18: Bulanan | Q18: Koordinator Edukasi | R18: Konfirmasi pagu dan realisasi anggaran | S18: Dummy | T18: Dummy | U18: Dummy | V18: =IF(OR(S18="Dummy",T18="Dummy",U18="Dummy"),"Mengandung Dummy",IF(OR(S18="Turunan",T18="Turunan",U18="Turunan"),"Turunan Laporan","Laporan")) -> Mengandung Dummy
A19: IND-012 | B19: 46203 | C19: A3 | D19: Road Safety Education Program | E19: Activity | F19: Edukasi/PPKL dan pemasangan spanduk dilaksanakan | G19: Kegiatan PPKL dan pemasangan spanduk bulan Juni | H19: Jumlah kegiatan yang selesai pada bulan berjalan | I19: 0 | J19: 9 | K19: 9 | L19: kegiatan | M19: =IFERROR(K19/J19,0) -> 1 | N19: =IF(K19="","Belum Ada Data",IF(M19>=1,"Tercapai",IF(M19>=0.8,"In Progress","Perlu Perhatian"))) -> Tercapai | O19: Activity 1.jpeg – A3 | P19: Bulanan | Q19: Koordinator Edukasi | R19: Lampirkan daftar sekolah dan dokumentasi | S19: Dummy | T19: Dummy | U19: Laporan | V19: =IF(OR(S19="Dummy",T19="Dummy",U19="Dummy"),"Mengandung Dummy",IF(OR(S19="Turunan",T19="Turunan",U19="Turunan"),"Turunan Laporan","Laporan")) -> Mengandung Dummy | W19: Target numerik tidak tercantum; laporan menyebut kegiatan sesuai target.
A20: IND-013 | B20: 46203 | C20: A3 | D20: Road Safety Education Program | E20: Output | F20: Program edukasi di sekolah dan program edukasi bagi pengajar. | G20: Kegiatan PPKL kumulatif s.d. Juni | H20: Jumlah kegiatan PPKL yang tercatat sejak Januari sampai Juni 2026 | I20: 0 | J20: 80 | K20: 80 | L20: kegiatan | M20: =IFERROR(K20/J20,0) -> 1 | N20: =IF(K20="","Belum Ada Data",IF(M20>=1,"Tercapai",IF(M20>=0.8,"In Progress","Perlu Perhatian"))) -> Tercapai | O20: Activity 1.jpeg – A3 | P20: Bulanan | Q20: Koordinator Edukasi | R20: Rekonsiliasi daftar kegiatan per sekolah | S20: Dummy | T20: Dummy | U20: Laporan | V20: =IF(OR(S20="Dummy",T20="Dummy",U20="Dummy"),"Mengandung Dummy",IF(OR(S20="Turunan",T20="Turunan",U20="Turunan"),"Turunan Laporan","Laporan")) -> Mengandung Dummy | W20: Target naratif: Key Activity Breakdown 5.jpeg.
A21: IND-014 | B21: 46203 | C21: A3 | D21: Road Safety Education Program | E21: Output | F21: Program edukasi di sekolah dan program edukasi bagi pengajar. | G21: Himbauan keselamatan terpasang s.d. Juni | H21: Jumlah himbauan/spanduk keselamatan yang terpasang | I21: 0 | J21: 45 | K21: 45 | L21: himbauan | M21: =IFERROR(K21/J21,0) -> 1 | N21: =IF(K21="","Belum Ada Data",IF(M21>=1,"Tercapai",IF(M21>=0.8,"In Progress","Perlu Perhatian"))) -> Tercapai | O21: Activity 1.jpeg – A3 | P21: Bulanan | Q21: Koordinator Edukasi | R21: Catat lokasi dan kondisi media | S21: Dummy | T21: Dummy | U21: Laporan | V21: =IF(OR(S21="Dummy",T21="Dummy",U21="Dummy"),"Mengandung Dummy",IF(OR(S21="Turunan",T21="Turunan",U21="Turunan"),"Turunan Laporan","Laporan")) -> Mengandung Dummy | W21: Target naratif: Key Activity Breakdown 5.jpeg.
A22: IND-015 | B22: 46203 | C22: A3 | D22: Road Safety Education Program | E22: Outcome | F22: 20% sekolah di Jawa Timur mendapatkan edukasi dan pengajar menjadi agen keselamatan di lingkungan keluarga dan sekolah/kampus. | G22: Peserta dengan kenaikan skor pengetahuan ≥20% | H22: Persentase peserta dengan skor pasca-sesi minimal 20% lebih tinggi dari pra-sesi | I22: 0.45 | J22: 0.7 | K22: 0.68 | L22: % peserta | M22: =IFERROR(K22/J22,0) -> 0.97142857 | N22: =IF(K22="","Belum Ada Data",IF(M22>=1,"Tercapai",IF(M22>=0.8,"In Progress","Perlu Perhatian"))) -> In Progress | O22: Belum ada pre/post-test | P22: Triwulanan | Q22: Koordinator Edukasi | R22: Gunakan pre/post-test singkat yang sama | S22: Dummy | T22: Dummy | U22: Dummy | V22: =IF(OR(S22="Dummy",T22="Dummy",U22="Dummy"),"Mengandung Dummy",IF(OR(S22="Turunan",T22="Turunan",U22="Turunan"),"Turunan Laporan","Laporan")) -> Mengandung Dummy | W22: Target naratif: Key Activity Breakdown 5.jpeg.
A23: IND-016 | B23: 46203 | C23: A3 | D23: Road Safety Education Program | E23: Impact | F23: Implementasi Penanganan Titik Rawan Laka 100% terintervensi (Data & Digital) | G23: Penurunan insiden kecelakaan di sekolah sasaran | H23: Persentase penurunan insiden dibanding periode pembanding | I23: 0 | J23: 0.1 | K23: 0.06 | L23: % penurunan | M23: =IFERROR(K23/J23,0) -> 0.6 | N23: =IF(K23="","Belum Ada Data",IF(M23>=1,"Tercapai",IF(M23>=0.8,"In Progress","Perlu Perhatian"))) -> Perlu Perhatian | O23: Belum ada data insiden | P23: Semesteran | Q23: Koordinator Edukasi | R23: Minta data insiden dari sekolah/mitra | S23: Dummy | T23: Dummy | U23: Dummy | V23: =IF(OR(S23="Dummy",T23="Dummy",U23="Dummy"),"Mengandung Dummy",IF(OR(S23="Turunan",T23="Turunan",U23="Turunan"),"Turunan Laporan","Laporan")) -> Mengandung Dummy | W23: Target naratif: Strategic Alignment 2.jpeg. Pemetaan impact perlu konfirmasi klien; skor memakai indikator impact Tracker sebagai proxy sampai KPI strategis diisi.
A24: IND-017 | B24: 46203 | C24: A4 | D24: Transport Driver Safety Program | E24: Input | F24: Sumber daya pemeriksaan dan edukasi pengemudi tersedia | G24: Anggaran program tersedia | H24: Anggaran yang dialokasikan dan direalisasikan untuk program keselamatan pengemudi | I24: 0 | J24: 80 | K24: 72 | L24: Rp juta | M24: =IFERROR(K24/J24,0) -> 0.9 | N24: =IF(K24="","Belum Ada Data",IF(M24>=1,"Tercapai",IF(M24>=0.8,"In Progress","Perlu Perhatian"))) -> In Progress | O24: Belum ada di laporan | P24: Bulanan | Q24: Koordinator Transport | R24: Konfirmasi pagu dan realisasi anggaran | S24: Dummy | T24: Dummy | U24: Dummy | V24: =IF(OR(S24="Dummy",T24="Dummy",U24="Dummy"),"Mengandung Dummy",IF(OR(S24="Turunan",T24="Turunan",U24="Turunan"),"Turunan Laporan","Laporan")) -> Mengandung Dummy
A25: IND-018 | B25: 46203 | C25: A4 | D25: Transport Driver Safety Program | E25: Activity | F25: Operasi gabungan dan ramp check dilaksanakan | G25: Loket melaksanakan operasi gabungan/ramp check | H25: Jumlah loket yang melaksanakan kegiatan | I25: 0 | J25: 8 | K25: 8 | L25: loket | M25: =IFERROR(K25/J25,0) -> 1 | N25: =IF(K25="","Belum Ada Data",IF(M25>=1,"Tercapai",IF(M25>=0.8,"In Progress","Perlu Perhatian"))) -> Tercapai | O25: Activity 1.jpeg – A4 | P25: Bulanan | Q25: Koordinator Transport | R25: Validasi denominator jumlah loket | S25: Dummy | T25: Dummy | U25: Turunan | V25: =IF(OR(S25="Dummy",T25="Dummy",U25="Dummy"),"Mengandung Dummy",IF(OR(S25="Turunan",T25="Turunan",U25="Turunan"),"Turunan Laporan","Laporan")) -> Mengandung Dummy | W25: Laporan menyebut semua loket; angka 8 diturunkan dari cakupan loket pada keluaran lain.
A26: IND-019 | B26: 46203 | C26: A4 | D26: Transport Driver Safety Program | E26: Activity | F26: Kampanye keselamatan pada kendaraan dilaksanakan | G26: Giat pemasangan stiker bulan Juni | H26: Jumlah giat pemasangan stiker keselamatan | I26: 0 | J26: 3 | K26: 3 | L26: kegiatan | M26: =IFERROR(K26/J26,0) -> 1 | N26: =IF(K26="","Belum Ada Data",IF(M26>=1,"Tercapai",IF(M26>=0.8,"In Progress","Perlu Perhatian"))) -> Tercapai | O26: Activity 1.jpeg – A4 | P26: Bulanan | Q26: Koordinator Transport | R26: Lampirkan daftar lokasi | S26: Dummy | T26: Dummy | U26: Laporan | V26: =IF(OR(S26="Dummy",T26="Dummy",U26="Dummy"),"Mengandung Dummy",IF(OR(S26="Turunan",T26="Turunan",U26="Turunan"),"Turunan Laporan","Laporan")) -> Mengandung Dummy
A27: IND-020 | B27: 46203 | C27: A4 | D27: Transport Driver Safety Program | E27: Output | F27: Pelatihan keselamatan bagi pengemudi angkutan umum dan kendaraan berat; Operasi Gabungan & Sosialisasi ODOL; kampanye keselamatan kepada mobil pengangkut barang (truck); MUKL. | G27: Stiker keselamatan terpasang | H27: Jumlah stiker keselamatan yang dipasang pada mobil penumpang umum | I27: 0 | J27: 33 | K27: 33 | L27: stiker | M27: =IFERROR(K27/J27,0) -> 1 | N27: =IF(K27="","Belum Ada Data",IF(M27>=1,"Tercapai",IF(M27>=0.8,"In Progress","Perlu Perhatian"))) -> Tercapai | O27: Activity 1.jpeg – A4 | P27: Bulanan | Q27: Koordinator Transport | R27: Simpan foto dan nomor kendaraan | S27: Dummy | T27: Dummy | U27: Laporan | V27: =IF(OR(S27="Dummy",T27="Dummy",U27="Dummy"),"Mengandung Dummy",IF(OR(S27="Turunan",T27="Turunan",U27="Turunan"),"Turunan Laporan","Laporan")) -> Mengandung Dummy | W27: Target naratif: Key Activity Breakdown 5.jpeg.
A28: IND-021 | B28: 46203 | C28: A4 | D28: Transport Driver Safety Program | E28: Output | F28: Pelatihan keselamatan bagi pengemudi angkutan umum dan kendaraan berat; Operasi Gabungan & Sosialisasi ODOL; kampanye keselamatan kepada mobil pengangkut barang (truck); MUKL. | G28: Kegiatan PPGD | H28: Jumlah kegiatan PPGD yang terlaksana | I28: 0 | J28: 17 | K28: 17 | L28: kegiatan | M28: =IFERROR(K28/J28,0) -> 1 | N28: =IF(K28="","Belum Ada Data",IF(M28>=1,"Tercapai",IF(M28>=0.8,"In Progress","Perlu Perhatian"))) -> Tercapai | O28: Activity 1.jpeg – A4 | P28: Bulanan | Q28: Koordinator Transport | R28: Rekonsiliasi peserta dan loket | S28: Dummy | T28: Dummy | U28: Laporan | V28: =IF(OR(S28="Dummy",T28="Dummy",U28="Dummy"),"Mengandung Dummy",IF(OR(S28="Turunan",T28="Turunan",U28="Turunan"),"Turunan Laporan","Laporan")) -> Mengandung Dummy | W28: Target naratif: Key Activity Breakdown 5.jpeg.
A29: IND-022 | B29: 46203 | C29: A4 | D29: Transport Driver Safety Program | E29: Output | F29: Pelatihan keselamatan bagi pengemudi angkutan umum dan kendaraan berat; Operasi Gabungan & Sosialisasi ODOL; kampanye keselamatan kepada mobil pengangkut barang (truck); MUKL. | G29: Kegiatan MUKL | H29: Jumlah kegiatan Mobil Unit Keselamatan Lalu Lintas | I29: 0 | J29: 11 | K29: 11 | L29: kegiatan | M29: =IFERROR(K29/J29,0) -> 1 | N29: =IF(K29="","Belum Ada Data",IF(M29>=1,"Tercapai",IF(M29>=0.8,"In Progress","Perlu Perhatian"))) -> Tercapai | O29: Activity 1.jpeg – A4 | P29: Bulanan | Q29: Koordinator Transport | R29: Catat terminal/PO yang dijangkau | S29: Dummy | T29: Dummy | U29: Laporan | V29: =IF(OR(S29="Dummy",T29="Dummy",U29="Dummy"),"Mengandung Dummy",IF(OR(S29="Turunan",T29="Turunan",U29="Turunan"),"Turunan Laporan","Laporan")) -> Mengandung Dummy | W29: Target naratif: Key Activity Breakdown 5.jpeg.
A30: IND-023 | B30: 46203 | C30: A4 | D30: Transport Driver Safety Program | E30: Output | F30: Pelatihan keselamatan bagi pengemudi angkutan umum dan kendaraan berat; Operasi Gabungan & Sosialisasi ODOL; kampanye keselamatan kepada mobil pengangkut barang (truck); MUKL. | G30: Peserta diklat pengemudi dan awak | H30: Jumlah peserta diklat bersama KNKT | I30: 0 | J30: 60 | K30: 60 | L30: peserta | M30: =IFERROR(K30/J30,0) -> 1 | N30: =IF(K30="","Belum Ada Data",IF(M30>=1,"Tercapai",IF(M30>=0.8,"In Progress","Perlu Perhatian"))) -> Tercapai | O30: Activity 1.jpeg – A4 | P30: Bulanan | Q30: Koordinator Transport | R30: Simpan daftar hadir dan hasil tes | S30: Dummy | T30: Dummy | U30: Laporan | V30: =IF(OR(S30="Dummy",T30="Dummy",U30="Dummy"),"Mengandung Dummy",IF(OR(S30="Turunan",T30="Turunan",U30="Turunan"),"Turunan Laporan","Laporan")) -> Mengandung Dummy | W30: Target naratif: Key Activity Breakdown 5.jpeg.
A31: IND-024 | B31: 46203 | C31: A4 | D31: Transport Driver Safety Program | E31: Outcome | F31: Pengemudi memahami batas kecepatan, muatan, dan aturan lalu lintas. | G31: Kendaraan lulus pemeriksaan keselamatan | H31: Persentase kendaraan yang memenuhi pemeriksaan keselamatan | I31: 0.75 | J31: 0.85 | K31: 0.82 | L31: % kendaraan | M31: =IFERROR(K31/J31,0) -> 0.96470588 | N31: =IF(K31="","Belum Ada Data",IF(M31>=1,"Tercapai",IF(M31>=0.8,"In Progress","Perlu Perhatian"))) -> In Progress | O31: Belum ada hasil ramp check terstruktur | P31: Triwulanan | Q31: Koordinator Transport | R31: Rekap lulus/tidak lulus per loket | S31: Dummy | T31: Dummy | U31: Dummy | V31: =IF(OR(S31="Dummy",T31="Dummy",U31="Dummy"),"Mengandung Dummy",IF(OR(S31="Turunan",T31="Turunan",U31="Turunan"),"Turunan Laporan","Laporan")) -> Mengandung Dummy | W31: Target naratif: Key Activity Breakdown 5.jpeg.
A32: IND-025 | B32: 46203 | C32: A4 | D32: Transport Driver Safety Program | E32: Impact | F32: Kecepatan Kepastian Jaminan Wilayah/Cabang (Pelayanan Publik) | G32: Penurunan kecelakaan pada pengemudi sasaran | H32: Persentase penurunan kecelakaan dibanding periode pembanding | I32: 0 | J32: 0.08 | K32: 0.05 | L32: % penurunan | M32: =IFERROR(K32/J32,0) -> 0.625 | N32: =IF(K32="","Belum Ada Data",IF(M32>=1,"Tercapai",IF(M32>=0.8,"In Progress","Perlu Perhatian"))) -> Perlu Perhatian | O32: Belum ada data kecelakaan terhubung | P32: Semesteran | Q32: Koordinator Transport | R32: Hubungkan daftar peserta dengan data insiden | S32: Dummy | T32: Dummy | U32: Dummy | V32: =IF(OR(S32="Dummy",T32="Dummy",U32="Dummy"),"Mengandung Dummy",IF(OR(S32="Turunan",T32="Turunan",U32="Turunan"),"Turunan Laporan","Laporan")) -> Mengandung Dummy | W32: Target naratif: Strategic Alignment 2.jpeg. Pemetaan impact perlu konfirmasi klien; skor memakai indikator impact Tracker sebagai proxy sampai KPI strategis diisi.
A33: IND-026 | B33: 46203 | C33: A5 | D33: Passenger & Public Awareness Campaign | E33: Input | F33: Sumber daya kampanye publik tersedia | G33: Anggaran program tersedia | H33: Anggaran yang dialokasikan dan direalisasikan untuk kampanye publik | I33: 0 | J33: 40 | K33: 37 | L33: Rp juta | M33: =IFERROR(K33/J33,0) -> 0.925 | N33: =IF(K33="","Belum Ada Data",IF(M33>=1,"Tercapai",IF(M33>=0.8,"In Progress","Perlu Perhatian"))) -> In Progress | O33: Belum ada di laporan | P33: Bulanan | Q33: Koordinator Kampanye | R33: Konfirmasi pagu dan realisasi anggaran | S33: Dummy | T33: Dummy | U33: Dummy | V33: =IF(OR(S33="Dummy",T33="Dummy",U33="Dummy"),"Mengandung Dummy",IF(OR(S33="Turunan",T33="Turunan",U33="Turunan"),"Turunan Laporan","Laporan")) -> Mengandung Dummy
A34: IND-027 | B34: 46203 | C34: A5 | D34: Passenger & Public Awareness Campaign | E34: Activity | F34: Pemasangan stiker di bus dilaksanakan | G34: Lokasi pemasangan stiker | H34: Jumlah lokasi pemasangan stiker keselamatan | I34: 0 | J34: 3 | K34: 3 | L34: lokasi | M34: =IFERROR(K34/J34,0) -> 1 | N34: =IF(K34="","Belum Ada Data",IF(M34>=1,"Tercapai",IF(M34>=0.8,"In Progress","Perlu Perhatian"))) -> Tercapai | O34: Activity 2.jpeg – A5 | P34: Bulanan | Q34: Koordinator Kampanye | R34: Lampirkan lokasi dan dokumentasi | S34: Dummy | T34: Dummy | U34: Laporan | V34: =IF(OR(S34="Dummy",T34="Dummy",U34="Dummy"),"Mengandung Dummy",IF(OR(S34="Turunan",T34="Turunan",U34="Turunan"),"Turunan Laporan","Laporan")) -> Mengandung Dummy
A35: IND-028 | B35: 46203 | C35: A5 | D35: Passenger & Public Awareness Campaign | E35: Activity | F35: Diklat keselamatan angkutan umum dilaksanakan | G35: Kegiatan diklat pengemudi dan awak | H35: Jumlah kegiatan diklat yang selesai | I35: 0 | J35: 1 | K35: 1 | L35: kegiatan | M35: =IFERROR(K35/J35,0) -> 1 | N35: =IF(K35="","Belum Ada Data",IF(M35>=1,"Tercapai",IF(M35>=0.8,"In Progress","Perlu Perhatian"))) -> Tercapai | O35: Activity 2.jpeg – A5 | P35: Bulanan | Q35: Koordinator Kampanye | R35: Simpan agenda dan materi | S35: Dummy | T35: Dummy | U35: Laporan | V35: =IF(OR(S35="Dummy",T35="Dummy",U35="Dummy"),"Mengandung Dummy",IF(OR(S35="Turunan",T35="Turunan",U35="Turunan"),"Turunan Laporan","Laporan")) -> Mengandung Dummy
A36: IND-029 | B36: 46203 | C36: A5 | D36: Passenger & Public Awareness Campaign | E36: Output | F36: Kampanye keselamatan di terminal dan perusahaan otobus; glorifikasi keselamatan melalui media sosial, event, dan publikasi. | G36: Stiker keselamatan terpasang | H36: Jumlah stiker keselamatan yang dipasang | I36: 0 | J36: 33 | K36: 33 | L36: stiker | M36: =IFERROR(K36/J36,0) -> 1 | N36: =IF(K36="","Belum Ada Data",IF(M36>=1,"Tercapai",IF(M36>=0.8,"In Progress","Perlu Perhatian"))) -> Tercapai | O36: Activity 2.jpeg – A5 | P36: Bulanan | Q36: Koordinator Kampanye | R36: Catat armada dan estimasi jangkauan | S36: Dummy | T36: Dummy | U36: Laporan | V36: =IF(OR(S36="Dummy",T36="Dummy",U36="Dummy"),"Mengandung Dummy",IF(OR(S36="Turunan",T36="Turunan",U36="Turunan"),"Turunan Laporan","Laporan")) -> Mengandung Dummy | W36: Target naratif: Key Activity Breakdown 4.jpeg.
A37: IND-030 | B37: 46203 | C37: A5 | D37: Passenger & Public Awareness Campaign | E37: Output | F37: Kampanye keselamatan di terminal dan perusahaan otobus; glorifikasi keselamatan melalui media sosial, event, dan publikasi. | G37: Peserta diklat | H37: Jumlah peserta yang mengikuti diklat | I37: 0 | J37: 60 | K37: 60 | L37: peserta | M37: =IFERROR(K37/J37,0) -> 1 | N37: =IF(K37="","Belum Ada Data",IF(M37>=1,"Tercapai",IF(M37>=0.8,"In Progress","Perlu Perhatian"))) -> Tercapai | O37: Activity 2.jpeg – A5 | P37: Bulanan | Q37: Koordinator Kampanye | R37: Simpan daftar hadir dan hasil tes | S37: Dummy | T37: Dummy | U37: Laporan | V37: =IF(OR(S37="Dummy",T37="Dummy",U37="Dummy"),"Mengandung Dummy",IF(OR(S37="Turunan",T37="Turunan",U37="Turunan"),"Turunan Laporan","Laporan")) -> Mengandung Dummy | W37: Target naratif: Key Activity Breakdown 4.jpeg.
A38: IND-031 | B38: 46203 | C38: A5 | D38: Passenger & Public Awareness Campaign | E38: Outcome | F38: Masyarakat lebih peduli dan sadar terhadap keselamatan berkendara dan sebagai penumpang transportasi umum. | G38: Peserta dengan kenaikan skor pengetahuan ≥20% | H38: Persentase peserta dengan kenaikan skor sesuai ambang | I38: 0.5 | J38: 0.75 | K38: 0.71 | L38: % peserta | M38: =IFERROR(K38/J38,0) -> 0.94666667 | N38: =IF(K38="","Belum Ada Data",IF(M38>=1,"Tercapai",IF(M38>=0.8,"In Progress","Perlu Perhatian"))) -> In Progress | O38: Belum ada pre/post-test | P38: Triwulanan | Q38: Koordinator Kampanye | R38: Tambahkan pre/post-test dan survei paparan | S38: Dummy | T38: Dummy | U38: Dummy | V38: =IF(OR(S38="Dummy",T38="Dummy",U38="Dummy"),"Mengandung Dummy",IF(OR(S38="Turunan",T38="Turunan",U38="Turunan"),"Turunan Laporan","Laporan")) -> Mengandung Dummy | W38: Target naratif: Key Activity Breakdown 4.jpeg.
A39: IND-032 | B39: 46203 | C39: A5 | D39: Passenger & Public Awareness Campaign | E39: Impact | F39: Efektivitas Pelaksanaan Forum Keselamatan Lalu Lintas 100% terlaksana (Kolaborasi Ekosistem) | G39: Penurunan insiden armada sasaran | H39: Persentase penurunan insiden pada armada yang dijangkau | I39: 0 | J39: 0.08 | K39: 0.04 | L39: % penurunan | M39: =IFERROR(K39/J39,0) -> 0.5 | N39: =IF(K39="","Belum Ada Data",IF(M39>=1,"Tercapai",IF(M39>=0.8,"In Progress","Perlu Perhatian"))) -> Perlu Perhatian | O39: Belum ada data insiden armada | P39: Semesteran | Q39: Koordinator Kampanye | R39: Minta data insiden dari operator | S39: Dummy | T39: Dummy | U39: Dummy | V39: =IF(OR(S39="Dummy",T39="Dummy",U39="Dummy"),"Mengandung Dummy",IF(OR(S39="Turunan",T39="Turunan",U39="Turunan"),"Turunan Laporan","Laporan")) -> Mengandung Dummy | W39: Target naratif: Strategic Alignment 2.jpeg. Pemetaan impact perlu konfirmasi klien; skor memakai indikator impact Tracker sebagai proxy sampai KPI strategis diisi.
A40: IND-033 | B40: 46203 | C40: A6 | D40: Community & Village Road Safety Moment | E40: Input | F40: Sumber daya edukasi komunitas dan PPGD tersedia | G40: Anggaran program tersedia | H40: Anggaran yang dialokasikan dan direalisasikan untuk program komunitas | I40: 0 | J40: 45 | K40: 40 | L40: Rp juta | M40: =IFERROR(K40/J40,0) -> 0.88888889 | N40: =IF(K40="","Belum Ada Data",IF(M40>=1,"Tercapai",IF(M40>=0.8,"In Progress","Perlu Perhatian"))) -> In Progress | O40: Belum ada di laporan | P40: Bulanan | Q40: Koordinator Komunitas | R40: Konfirmasi pagu dan realisasi anggaran | S40: Dummy | T40: Dummy | U40: Dummy | V40: =IF(OR(S40="Dummy",T40="Dummy",U40="Dummy"),"Mengandung Dummy",IF(OR(S40="Turunan",T40="Turunan",U40="Turunan"),"Turunan Laporan","Laporan")) -> Mengandung Dummy
A41: IND-034 | B41: 46203 | C41: A6 | D41: Community & Village Road Safety Moment | E41: Activity | F41: Kampanye keselamatan saat survei korban dilaksanakan | G41: Sesi kampanye pada survei korban/ahli waris | H41: Jumlah sesi kampanye yang terdokumentasi | I41: 0 | J41: 20 | K41: 18 | L41: sesi | M41: =IFERROR(K41/J41,0) -> 0.9 | N41: =IF(K41="","Belum Ada Data",IF(M41>=1,"Tercapai",IF(M41>=0.8,"In Progress","Perlu Perhatian"))) -> In Progress | O41: Activity 2.jpeg – A6 (tanpa jumlah) | P41: Bulanan | Q41: Koordinator Komunitas | R41: Rekap jumlah survei dan bukti pemberian pesan | S41: Dummy | T41: Dummy | U41: Dummy | V41: =IF(OR(S41="Dummy",T41="Dummy",U41="Dummy"),"Mengandung Dummy",IF(OR(S41="Turunan",T41="Turunan",U41="Turunan"),"Turunan Laporan","Laporan")) -> Mengandung Dummy
A42: IND-035 | B42: 46203 | C42: A6 | D42: Community & Village Road Safety Moment | E42: Activity | F42: Sosialisasi keselamatan tingkat desa dilaksanakan | G42: Kelurahan/desa dengan spanduk keselamatan | H42: Jumlah kelurahan/desa yang memasang spanduk | I42: 0 | J42: 5 | K42: 4 | L42: wilayah | M42: =IFERROR(K42/J42,0) -> 0.8 | N42: =IF(K42="","Belum Ada Data",IF(M42>=1,"Tercapai",IF(M42>=0.8,"In Progress","Perlu Perhatian"))) -> In Progress | O42: Activity 2.jpeg – A6 (beberapa kelurahan) | P42: Bulanan | Q42: Koordinator Komunitas | R42: Ganti angka dummy dengan daftar wilayah | S42: Dummy | T42: Dummy | U42: Dummy | V42: =IF(OR(S42="Dummy",T42="Dummy",U42="Dummy"),"Mengandung Dummy",IF(OR(S42="Turunan",T42="Turunan",U42="Turunan"),"Turunan Laporan","Laporan")) -> Mengandung Dummy
A43: IND-036 | B43: 46203 | C43: A6 | D43: Community & Village Road Safety Moment | E43: Output | F43: Kampanye keselamatan di komunitas; safety talk komunitas & ahli waris; pemetaan desa dengan korban kecelakaan tertinggi; sosialisasi keselamatan bagi perangkat desa. | G43: Kegiatan PPGD | H43: Jumlah kegiatan PPGD yang terlaksana | I43: 0 | J43: 17 | K43: 17 | L43: kegiatan | M43: =IFERROR(K43/J43,0) -> 1 | N43: =IF(K43="","Belum Ada Data",IF(M43>=1,"Tercapai",IF(M43>=0.8,"In Progress","Perlu Perhatian"))) -> Tercapai | O43: Activity 2.jpeg – A6 | P43: Bulanan | Q43: Koordinator Komunitas | R43: Rekonsiliasi peserta dan materi | S43: Dummy | T43: Dummy | U43: Laporan | V43: =IF(OR(S43="Dummy",T43="Dummy",U43="Dummy"),"Mengandung Dummy",IF(OR(S43="Turunan",T43="Turunan",U43="Turunan"),"Turunan Laporan","Laporan")) -> Mengandung Dummy | W43: Target naratif: Key Activity Breakdown 4.jpeg.
...

Sheet Rantai ToC
A1: RANTAI THEORY OF CHANGE – PROGRAM JAWA TIMUR
A2: Hipotesis perubahan: Input → Activity → Output → Outcome → Impact. Output/Outcome mengikuti Key Activity Breakdown; Impact mengikuti Strategic Alignment melalui pemetaan kerja yang dapat diaudit. | B2: Hipotesis perubahan: Input → Activity → Output → Outcome → Impact. Output/Outcome mengikuti Key Activity Breakdown; Impact mengikuti Strategic Alignment melalui pemetaan kerja yang dapat diaudit. | C2: Hipotesis perubahan: Input → Activity → Output → Outcome → Impact. Output/Outcome mengikuti Key Activity Breakdown; Impact mengikuti Strategic Alignment melalui pemetaan kerja yang dapat diaudit. | D2: Hipotesis perubahan: Input → Activity → Output → Outcome → Impact. Output/Outcome mengikuti Key Activity Breakdown; Impact mengikuti Strategic Alignment melalui pemetaan kerja yang dapat diaudit. | E2: Hipotesis perubahan: Input → Activity → Output → Outcome → Impact. Output/Outcome mengikuti Key Activity Breakdown; Impact mengikuti Strategic Alignment melalui pemetaan kerja yang dapat diaudit. | F2: Hipotesis perubahan: Input → Activity → Output → Outcome → Impact. Output/Outcome mengikuti Key Activity Breakdown; Impact mengikuti Strategic Alignment melalui pemetaan kerja yang dapat diaudit. | G2: Hipotesis perubahan: Input → Activity → Output → Outcome → Impact. Output/Outcome mengikuti Key Activity Breakdown; Impact mengikuti Strategic Alignment melalui pemetaan kerja yang dapat diaudit. | H2: Hipotesis perubahan: Input → Activity → Output → Outcome → Impact. Output/Outcome mengikuti Key Activity Breakdown; Impact mengikuti Strategic Alignment melalui pemetaan kerja yang dapat diaudit.
A3: Hipotesis perubahan: Input → Activity → Output → Outcome → Impact. Output/Outcome mengikuti Key Activity Breakdown; Impact mengikuti Strategic Alignment melalui pemetaan kerja yang dapat diaudit. | B3: Hipotesis perubahan: Input → Activity → Output → Outcome → Impact. Output/Outcome mengikuti Key Activity Breakdown; Impact mengikuti Strategic Alignment melalui pemetaan kerja yang dapat diaudit. | C3: Hipotesis perubahan: Input → Activity → Output → Outcome → Impact. Output/Outcome mengikuti Key Activity Breakdown; Impact mengikuti Strategic Alignment melalui pemetaan kerja yang dapat diaudit. | D3: Hipotesis perubahan: Input → Activity → Output → Outcome → Impact. Output/Outcome mengikuti Key Activity Breakdown; Impact mengikuti Strategic Alignment melalui pemetaan kerja yang dapat diaudit. | E3: Hipotesis perubahan: Input → Activity → Output → Outcome → Impact. Output/Outcome mengikuti Key Activity Breakdown; Impact mengikuti Strategic Alignment melalui pemetaan kerja yang dapat diaudit. | F3: Hipotesis perubahan: Input → Activity → Output → Outcome → Impact. Output/Outcome mengikuti Key Activity Breakdown; Impact mengikuti Strategic Alignment melalui pemetaan kerja yang dapat diaudit. | G3: Hipotesis perubahan: Input → Activity → Output → Outcome → Impact. Output/Outcome mengikuti Key Activity Breakdown; Impact mengikuti Strategic Alignment melalui pemetaan kerja yang dapat diaudit. | H3: Hipotesis perubahan: Input → Activity → Output → Outcome → Impact. Output/Outcome mengikuti Key Activity Breakdown; Impact mengikuti Strategic Alignment melalui pemetaan kerja yang dapat diaudit.
A5: Kode | B5: Program | C5: Input | D5: Activity | E5: Output | F5: Outcome | G5: Impact | H5: Asumsi Kunci / Faktor Eksternal
A6: A3 | B6: Road Safety Education Program | C6: Anggaran, fasilitator/PPKL, materi edukasi, spanduk, akses sekolah | D6: Edukasi/sosialisasi di sekolah; PPKL; pemasangan spanduk | E6: Program edukasi di sekolah dan program edukasi bagi pengajar. | F6: 20% sekolah di Jawa Timur mendapatkan edukasi dan pengajar menjadi agen keselamatan di lingkungan keluarga dan sekolah/kampus. Cara ukur: Dokumentasi kegiatan; Laporan Andalan. | G6: Implementasi Penanganan Titik Rawan Laka 100% terintervensi (Data & Digital) | H6: KBI strategis: Menggunakan data kecelakaan sebagai dasar identifikasi dan prioritas intervensi Alignment: Intervensi keselamatan berbasis data Sumber: Key Activity Breakdown 5.jpeg; Strategic Alignment 2.jpeg. Pemetaan impact perlu konfirmasi klien.
A7: A4 | B7: Transport Driver Safety Program | C7: Anggaran, petugas, alat ramp check, stiker, instruktur, dukungan loket | D7: Operasi gabungan/ramp check; kampanye; PPGD; MUKL; diklat | E7: Pelatihan keselamatan bagi pengemudi angkutan umum dan kendaraan berat; Operasi Gabungan & Sosialisasi ODOL; kampanye keselamatan kepada mobil pengangkut barang (truck); MUKL. | F7: Pengemudi memahami batas kecepatan, muatan, dan aturan lalu lintas. Cara ukur: Laporan Andalan; dokumentasi kegiatan. | G7: Kecepatan Kepastian Jaminan Wilayah/Cabang (Pelayanan Publik) | H7: KBI strategis: Respons cepat dan koordinasi efektif antar unit dalam proses penjaminan korban laka Alignment: Meningkatkan kualitas dan kecepatan pelayanan publik Sumber: Key Activity Breakdown 5.jpeg; Strategic Alignment 2.jpeg. Pemetaan impact perlu konfirmasi klien.
A8: A5 | B8: Passenger & Public Awareness Campaign | C8: Anggaran, media kampanye, trainer, kanal WA/Instagram, akses terminal/PO | D8: Pemasangan stiker; glorifikasi pesan; kampanye; diklat | E8: Kampanye keselamatan di terminal dan perusahaan otobus; glorifikasi keselamatan melalui media sosial, event, dan publikasi. | F8: Masyarakat lebih peduli dan sadar terhadap keselamatan berkendara dan sebagai penumpang transportasi umum. Cara ukur: Dokumentasi kegiatan; survei. | G8: Efektivitas Pelaksanaan Forum Keselamatan Lalu Lintas 100% terlaksana (Kolaborasi Ekosistem) | H8: KBI strategis: Proaktif membangun koordinasi lintas instansi serta memastikan tindak lanjut hasil forum Alignment: Memperkuat kolaborasi ekosistem keselamatan Sumber: Key Activity Breakdown 4.jpeg; Strategic Alignment 2.jpeg. Pemetaan impact perlu konfirmasi klien.
A9: A6 | B9: Community & Village Road Safety Moment | C9: Anggaran, petugas, souvenir/pesan keselamatan, spanduk, trainer PPGD | D9: Kampanye saat survei korban; sosialisasi desa; PPGD | E9: Kampanye keselamatan di komunitas; safety talk komunitas & ahli waris; pemetaan desa dengan korban kecelakaan tertinggi; sosialisasi keselamatan bagi perangkat desa. | F9: Perangkat desa aktif menyampaikan pesan keselamatan kepada masyarakat desa; masyarakat paham dan aktif menyuarakan keselamatan lalu lintas. Cara ukur: Dokumentasi kegiatan & laporan pelaksanaan; jumlah komunitas terlibat. | G9: Kecepatan Kepastian Jaminan Wilayah/Cabang (Pelayanan Publik) | H9: KBI strategis: Respons cepat dan koordinasi efektif antar unit dalam proses penjaminan korban laka Alignment: Meningkatkan kualitas dan kecepatan pelayanan publik Sumber: Key Activity Breakdown 4.jpeg; Strategic Alignment 2.jpeg. Pemetaan impact perlu konfirmasi klien.
A10: A7 | B10: Stakeholder Collaborative Action | C10: Anggaran, jejaring RS/BPJS/mitra, forum, staf koordinasi | D10: Sharing and Caring; aksi simpatik; FKLLJ/FLLAJ | E10: Sharing & Caring RS; Forum Lalu Lintas Angkutan Jalan (FLLAJ); aksi simpatik. | F10: Intervensi setiap stakeholder tepat sasaran di masyarakat; masyarakat patuh dan sadar berkendara. Cara ukur: Dokumentasi kegiatan; notulensi. | G10: Efektivitas Pelaksanaan Forum Keselamatan Lalu Lintas 100% terlaksana (Kolaborasi Ekosistem) | H10: KBI strategis: Proaktif membangun koordinasi lintas instansi serta memastikan tindak lanjut hasil forum Alignment: Memperkuat kolaborasi ekosistem keselamatan Sumber: Key Activity Breakdown 3.jpeg; Strategic Alignment 2.jpeg. Pemetaan impact perlu konfirmasi klien.
A11: A1 | B11: Road Safety Baseline Study & Data Mapping | C11: Data kecelakaan/santunan, analis, dan forum penyamaan persepsi | D11: Studi baseline dan pemetaan data keselamatan jalan | E11: Road safety insight report; data korban kecelakaan dan santunan; faktor penyebab kecelakaan. | F11: Tersedianya data kecelakaan sebagai dasar Program JAWA TIMUR dan setiap intervensi JAWA TIMUR berbasis data. Cara ukur: Laporan Bidang Pelayanan; Dashboard CERI. | G11: Implementasi Penanganan Titik Rawan Laka 100% terintervensi (Data & Digital) | H11: KBI strategis: Menggunakan data kecelakaan sebagai dasar identifikasi dan prioritas intervensi Alignment: Intervensi keselamatan berbasis data Sumber: Key Activity Breakdown 6.jpeg; Strategic Alignment 2.jpeg. Pemetaan impact perlu konfirmasi klien.
A12: A2 | B12: Blackspot Intervention Program | C12: Peta blackspot, data baseline, petugas pelayanan, dan dukungan stakeholder | D12: Perancangan dan pelaksanaan intervensi titik rawan | E12: Rekomendasi kegiatan atau intervensi berdasarkan pemetaan, seperti rambu, edukasi, dan intervensi relevan lainnya. | F12: Stakeholder melakukan intervensi pada titik rawan dan koordinasi lintas lembaga meningkat. Cara ukur: Laporan Andalan; monthly report Bidang Pelayanan. | G12: Implementasi Penanganan Titik Rawan Laka 100% terintervensi (Data & Digital) | H12: KBI strategis: Menggunakan data kecelakaan sebagai dasar identifikasi dan prioritas intervensi Alignment: Intervensi keselamatan berbasis data Sumber: Key Activity Breakdown 6.jpeg; Strategic Alignment 2.jpeg. Pemetaan impact perlu konfirmasi klien.
A13: A8 | B13: Monitoring, Review & Impact Evaluation | C13: Data monitoring, tim evaluasi, forum review, dan dukungan pimpinan | D13: Monitoring, review, dan evaluasi dampak berkala | E13: Laporan evaluasi Program JAWA TIMUR; rekomendasi program lanjutan; pengambilan keputusan berbasis data evaluasi. | F13: Organisasi menggunakan data untuk meningkatkan program kesamsatan. Cara ukur: Dokumentasi kegiatan; laporan evaluasi. | G13: Anev Pelayanan Luar Biasa 100% (Agility & Learning) | H13: KBI strategis: Melakukan evaluasi rutin berbasis data serta terbuka terhadap perbaikan layanan Alignment: Mendorong perbaikan layanan berkelanjutan Sumber: Key Activity Breakdown 3.jpeg; Strategic Alignment 2.jpeg. Pemetaan impact perlu konfirmasi klien.
A14: A9 | B14: Personal Growth & Digital Skills | C14: Change Catalyst, dukungan HC, kontributor cabang, dan perangkat digital | D14: Sesi personal growth, digital skills, dan content creation | E14: Ide dan draft content creation. | F14: Ide atau praktik kerja dibagikan dan mulai dicoba atau diadaptasi oleh unit lain; peningkatan skill pegawai terdokumentasi. Cara ukur: Beberapa unit mencoba praktik design dari NEXTalk; laporan/dokumentasi peningkatan skill pegawai. | G14: GAP Kompetensi Pegawai Organik <30% (Learning & Growth) | H14: KBI strategis: Menggunakan data sebagai dasar keputusan Alignment: Penutupan gap kompetensi berbasis praktik nyata Sumber: Key Activity Breakdown 1.jpeg; Strategic Alignment 1.jpeg. Pemetaan impact perlu konfirmasi klien.
... A17: A12 | B17: Inspiring Champion Award | C17: Kriteria penghargaan, proses nominasi, penilai, dan dokumentasi kontribusi | D17: Seleksi dan pemberian Inspiring Champion Award | E17: Penerima penghargaan Inspiring Champion berdasarkan kriteria penilaian. | F17: Meningkatnya motivasi pegawai untuk berpartisipasi sebagai narasumber maupun kontributor. Cara ukur: ≥70% peserta menyatakan kegiatan NEXTalk memberikan inspirasi atau pengetahuan baru. | G17: Peningkatan Kompetensi Pegawai (IDP) | H17: KBI strategis: Adaptif terhadap sistem dan timeline Alignment: Menguatkan pemahaman aplikatif Sumber: Key Activity Breakdown 1.jpeg; Strategic Alignment 1.jpeg. Pemetaan impact perlu konfirmasi klien.

Sheet Data Sumber
A1: DATA SUMBER – LAPORAN AKTIVITAS & TARGET PROGRAM | B1: DATA SUMBER – LAPORAN AKTIVITAS & TARGET PROGRAM | C1: DATA SUMBER – LAPORAN AKTIVITAS & TARGET PROGRAM | D1: DATA SUMBER – LAPORAN AKTIVITAS & TARGET PROGRAM | E1: DATA SUMBER – LAPORAN AKTIVITAS & TARGET PROGRAM | F1: DATA SUMBER – LAPORAN AKTIVITAS & TARGET PROGRAM | G1: DATA SUMBER – LAPORAN AKTIVITAS & TARGET PROGRAM | H1: DATA SUMBER – LAPORAN AKTIVITAS & TARGET PROGRAM | I1: DATA SUMBER – LAPORAN AKTIVITAS & TARGET PROGRAM
A2: Transkripsi ringkas untuk audit dari Activity 1–3.jpeg, Key Activity Breakdown 1–6.jpeg, dan Strategic Alignment 1–2.jpeg. Nilai dummy tetap ditandai pada Tracker ToC dan Scorecard ToC. | B2: Transkripsi ringkas untuk audit dari Activity 1–3.jpeg, Key Activity Breakdown 1–6.jpeg, dan Strategic Alignment 1–2.jpeg. Nilai dummy tetap ditandai pada Tracker ToC dan Scorecard ToC. | C2: Transkripsi ringkas untuk audit dari Activity 1–3.jpeg, Key Activity Breakdown 1–6.jpeg, dan Strategic Alignment 1–2.jpeg. Nilai dummy tetap ditandai pada Tracker ToC dan Scorecard ToC. | D2: Transkripsi ringkas untuk audit dari Activity 1–3.jpeg, Key Activity Breakdown 1–6.jpeg, dan Strategic Alignment 1–2.jpeg. Nilai dummy tetap ditandai pada Tracker ToC dan Scorecard ToC. | E2: Transkripsi ringkas untuk audit dari Activity 1–3.jpeg, Key Activity Breakdown 1–6.jpeg, dan Strategic Alignment 1–2.jpeg. Nilai dummy tetap ditandai pada Tracker ToC dan Scorecard ToC. | F2: Transkripsi ringkas untuk audit dari Activity 1–3.jpeg, Key Activity Breakdown 1–6.jpeg, dan Strategic Alignment 1–2.jpeg. Nilai dummy tetap ditandai pada Tracker ToC dan Scorecard ToC. | G2: Transkripsi ringkas untuk audit dari Activity 1–3.jpeg, Key Activity Breakdown 1–6.jpeg, dan Strategic Alignment 1–2.jpeg. Nilai dummy tetap ditandai pada Tracker ToC dan Scorecard ToC. | H2: Transkripsi ringkas untuk audit dari Activity 1–3.jpeg, Key Activity Breakdown 1–6.jpeg, dan Strategic Alignment 1–2.jpeg. Nilai dummy tetap ditandai pada Tracker ToC dan Scorecard ToC. | I2: Transkripsi ringkas untuk audit dari Activity 1–3.jpeg, Key Activity Breakdown 1–6.jpeg, dan Strategic Alignment 1–2.jpeg. Nilai dummy tetap ditandai pada Tracker ToC dan Scorecard ToC.
A3: Transkripsi ringkas untuk audit dari Activity 1–3.jpeg, Key Activity Breakdown 1–6.jpeg, dan Strategic Alignment 1–2.jpeg. Nilai dummy tetap ditandai pada Tracker ToC dan Scorecard ToC. | B3: Transkripsi ringkas untuk audit dari Activity 1–3.jpeg, Key Activity Breakdown 1–6.jpeg, dan Strategic Alignment 1–2.jpeg. Nilai dummy tetap ditandai pada Tracker ToC dan Scorecard ToC. | C3: Transkripsi ringkas untuk audit dari Activity 1–3.jpeg, Key Activity Breakdown 1–6.jpeg, dan Strategic Alignment 1–2.jpeg. Nilai dummy tetap ditandai pada Tracker ToC dan Scorecard ToC. | D3: Transkripsi ringkas untuk audit dari Activity 1–3.jpeg, Key Activity Breakdown 1–6.jpeg, dan Strategic Alignment 1–2.jpeg. Nilai dummy tetap ditandai pada Tracker ToC dan Scorecard ToC. | E3: Transkripsi ringkas untuk audit dari Activity 1–3.jpeg, Key Activity Breakdown 1–6.jpeg, dan Strategic Alignment 1–2.jpeg. Nilai dummy tetap ditandai pada Tracker ToC dan Scorecard ToC. | F3: Transkripsi ringkas untuk audit dari Activity 1–3.jpeg, Key Activity Breakdown 1–6.jpeg, dan Strategic Alignment 1–2.jpeg. Nilai dummy tetap ditandai pada Tracker ToC dan Scorecard ToC. | G3: Transkripsi ringkas untuk audit dari Activity 1–3.jpeg, Key Activity Breakdown 1–6.jpeg, dan Strategic Alignment 1–2.jpeg. Nilai dummy tetap ditandai pada Tracker ToC dan Scorecard ToC. | H3: Transkripsi ringkas untuk audit dari Activity 1–3.jpeg, Key Activity Breakdown 1–6.jpeg, dan Strategic Alignment 1–2.jpeg. Nilai dummy tetap ditandai pada Tracker ToC dan Scorecard ToC. | I3: Transkripsi ringkas untuk audit dari Activity 1–3.jpeg, Key Activity Breakdown 1–6.jpeg, dan Strategic Alignment 1–2.jpeg. Nilai dummy tetap ditandai pada Tracker ToC dan Scorecard ToC.
A5: No. | B5: Berkas | C5: Kode | D5: Program | E5: Kategori | F5: Pernyataan Sumber (ringkas) | G5: Nilai | H5: Satuan | I5: Catatan
A6: 1 | B6: Activity 1.jpeg | C6: A3 | D6: Road Safety Education Program | E6: Realisasi | F6: Kegiatan PPKL dan pemasangan spanduk di sekolah pada Juni 2026 | G6: 9 | H6: kegiatan
A7: 2 | B7: Activity 1.jpeg | C7: A3 | D7: Road Safety Education Program | E7: Realisasi | F7: Kegiatan PPKL kumulatif s.d. Juni 2026 | G7: 80 | H7: kegiatan
A8: 3 | B8: Activity 1.jpeg | C8: A3 | D8: Road Safety Education Program | E8: Realisasi | F8: Himbauan keselamatan kumulatif s.d. Juni 2026 | G8: 45 | H8: himbauan
A9: 4 | B9: Activity 1.jpeg | C9: A4 | D9: Transport Driver Safety Program | E9: Realisasi | F9: Operasi gabungan/ramp check dilaksanakan oleh semua loket | H9: loket | I9: Jumlah loket tidak dinyatakan pada kalimat ini
A10: 5 | B10: Activity 1.jpeg | C10: A4 | D10: Transport Driver Safety Program | E10: Realisasi | F10: Giat pemasangan stiker pada Juni | G10: 3 | H10: kegiatan
A11: 6 | B11: Activity 1.jpeg | C11: A4 | D11: Transport Driver Safety Program | E11: Realisasi | F11: Stiker keselamatan pada mobil penumpang umum | G11: 33 | H11: stiker
A12: 7 | B12: Activity 1.jpeg | C12: A4 | D12: Transport Driver Safety Program | E12: Realisasi | F12: Kegiatan PPGD oleh 8 loket | G12: 17 | H12: kegiatan | I12: Cakupan 8 loket
A13: 8 | B13: Activity 1.jpeg | C13: A4 | D13: Transport Driver Safety Program | E13: Realisasi | F13: Kegiatan MUKL oleh 8 loket | G13: 11 | H13: kegiatan | I13: Cakupan 8 loket
A14: 9 | B14: Activity 1.jpeg | C14: A4 | D14: Transport Driver Safety Program | E14: Realisasi | F14: Diklat Pengemudi dan Awak bersama KNKT | G14: 1 | H14: kegiatan
A15: 10 | B15: Activity 1.jpeg | C15: A4 | D15: Transport Driver Safety Program | E15: Realisasi | F15: Peserta diklat pengemudi dan awak | G15: 60 | H15: peserta
A16: 11 | B16: Activity 2.jpeg | C16: A5 | D16: Passenger & Public Awareness Campaign | E16: Realisasi | F16: Lokasi pemasangan stiker | G16: 3 | H16: lokasi | I16: Sebanyak 33 stiker
A17: 12 | B17: Activity 2.jpeg | C17: A5 | D17: Passenger & Public Awareness Campaign | E17: Realisasi | F17: Diklat Pengemudi dan Awak Angkutan Umum | G17: 1 | H17: kegiatan | I17: Diikuti 60 peserta
A18: 13 | B18: Activity 2.jpeg | C18: A6 | D18: Community & Village Road Safety Moment | E18: Realisasi | F18: Kampanye disampaikan pada setiap survei korban/ahli waris | H18: sesi | I18: Jumlah survei tidak dicantumkan
